Workbook

Sheet Item_Master
A1: ID | B1: Name | C1: Description | D1: UseDescription | E1: ItemType | F1: Rarity | G1: AtlasGroup
A2: Nimbus_Cudgel | B2: STR_NIMBUS_CUDGEL_NAME | C2: STR_NIMBUS_CUDGEL_DES | D2: STR_NIMBUS_CUDGEL_SKILL | E2: Weapon | F2: Legendary
A3: Triple_Edged_Blade | B3: STR_TRIPLE_EDGED_BLADE_NAME | C3: STR_TRIPLE_EDGED_BLADE_DES | D3: STR_TRIPLE_EDGED_BLADE_SKILL | E3: Weapon | F3: Legendary
A4: Vanguard_Of_Volition | B4: STR_VANGUARD_OF_VOLITION_NAME | C4: STR_VANGUARD_OF_VOLITION_DES | D4: STR_VANGUARD_OF_VOLITION_SKILL | E4: Weapon | F4: Legendary
A5: Ninefold_Staff | B5: STR_NINEFOLD_STAFF_NAME | C5: STR_NINEFOLD_STAFF_DES | D5: STR_NINEFOLD_STAFF_SKILL | E5: Weapon | F5: Rare
A6: Nine_ToolThed_Rake | B6: STR_NINE_TOOLTHED_RAKE_NAME | C6: STR_NINE_TOOLTHED_RAKE_DES | D6: STR_NINE_TOOLTHED_RAKE_SKILL | E6: Weapon | F6: Legendary
A7: Nimbus_Cloud | B7: STR_NIMBUS_CLOUD_NAME | C7: STR_NIMBUS_CLOUD_DES | D7: STR_NIMBUS_CLOUD_SKILL | E7: Weapon | F7: Rare
A8: Sunburst_Spade | B8: STR_SUNBURST_SPADE_NAME | C8: STR_SUNBURST_SPADE_DES | D8: STR_SUNBURST_SPADE_SKILL | E8: Weapon | F8: Common
A9: Reincarnation | B9: STR_REINCARNATION_NAME | C9: STR_REINCARNATION_DES | D9: STR_REINCARNATION_SKILL | E9: Weapon | F9: Epic
A10: Ennead_spear | B10: STR_ENNEAD_SPEAR_NAME | C10: STR_ENNEAD_SPEAR_DES | D10: STR_ENNEAD_SPEAR_SKILL | E10: Weapon | F10: Uncommon
A11: Crescent_Axe | B11: STR_CRESCENT_AXE_NAME | C11: STR_CRESCENT_AXE_DES | D11: STR_CRESCENT_AXE_SKILL | E11: Weapon | F11: Common
A12: Bronze_Hammer | B12: STR_BRONZE_HAMMER_NAME | C12: STR_BRONZE_HAMMER_DES | D12: STR_BRONZE_HAMMER_SKILL | E12: Weapon | F12: Uncommon
A13: Moonlit_Firelfy | B13: STR_MOONLIT_FIREFLY_NAME | C13: STR_MOONLIT_FIREFLY_DES | D13: STR_MOONLIT_FIREFLY_SKILL | E13: Weapon | F13: Legendary
... A65: supreme_exp | B65: STR_SUPREME_EXP | C65: STR_EXP_DESCRIPTION | D65: STR_EXP_USEFUL | E65: Exp | F65: Legendary
A66: SunWukong | B66: STR_SUN_WUKONG | C66: STR_SHARD_DESCRIPTION | E66: Shard | F66: Legendary
A67: TangSanZang | B67: STR_TANG_SANZANG | C67: STR_SHARD_DESCRIPTION | E67: Shard | F67: Uncommon
A68: ZhuBaJie | B68: STR_ZHU_BAIJE | C68: STR_SHARD_DESCRIPTION | E68: Shard | F68: Epic
A69: ShaWujing | B69: STR_SHA_WUJING | C69: STR_SHARD_DESCRIPTION | E69: Shard | F69: Rare
A70: DragonKing | B70: STR_DRAGON_KING_EATERN_SEA | C70: STR_SHARD_DESCRIPTION | E70: Shard | F70: Rare
A71: ThirdPrinceNezha | B71: STR_THIRD_PRINCE_NEZHA | C71: STR_SHARD_DESCRIPTION | E71: Shard | F71: Legendary
A72: LittleWhiteDragon | B72: STR_LITTLE_WHITE_DRAGON | C72: STR_SHARD_DESCRIPTION | E72: Shard | F72: Common
A73: BullDemonKing | B73: STR_BULL_DEMON_KING | C73: STR_SHARD_DESCRIPTION | E73: Shard | F73: Legendary
A74: ErlangShen | B74: STR_ERLANG_SHEN_YANG_JIAN | C74: STR_SHARD_DESCRIPTION | E74: Shard | F74: Legendary
A75: LiJing | B75: STR_LI_JING | C75: STR_SHARD_DESCRIPTION | E75: Shard | F75: Legendary
A76: VanguardTiger | B76: STR_VANGUARD_TIGER | C76: STR_SHARD_DESCRIPTION | E76: Shard | F76: Common
A77: TheBoySage | B77: STR_THE_BOY_SAGE | C77: STR_SHARD_DESCRIPTION | E77: Shard | F77: Legendary
... A81: GoldfishDemon | B81: STR_GOLD_FISH_DEMON | C81: STR_SHARD_DESCRIPTION | E81: Shard | F81: Epic
A82: Armor01_Helmet | B82: STR_ARMOR_01 | E82: Armor | F82: Legendary
A83: Armor02_Helmet | B83: STR_ARMOR_02 | E83: Armor | F83: Rare
A84: Armor03_Helmet | B84: STR_ARMOR_03 | E84: Armor | F84: Uncommon
A85: Armor04_Helmet | B85: STR_ARMOR_04 | E85: Armor | F85: Epic
A86: Armor05_Helmet | B86: STR_ARMOR_05 | E86: Armor | F86: Common
A87: Armor06_Helmet | B87: STR_ARMOR_06 | E87: Armor | F87: Epic
A88: Armor07_Helmet | B88: STR_ARMOR_07 | E88: Armor | F88: Legendary
A89: Armor08_Helmet | B89: STR_ARMOR_08 | E89: Armor | F89: Legendary
A90: Armor01_Chestplate | B90: STR_ARMOR_01 | E90: Armor | F90: Legendary
A91: Armor02_Chestplate | B91: STR_ARMOR_02 | E91: Armor | F91: Rare
A92: Armor03_Chestplate | B92: STR_ARMOR_03 | E92: Armor | F92: Uncommon
A93: Armor04_Chestplate | B93: STR_ARMOR_04 | E93: Armor | F93: Epic
... A129: Armor08_Ring | B129: STR_ARMOR_08 | E129: Armor | F129: Legendary
...

Sheet Item_Detail
A1: ID | B1: Pram01 | C1: Pram02 | D1: Pram03 | E1: Pram04 | F1: Pram05
A2: common_exp | B2: 100
A3: fine_exp | B3: 400
A4: rare_exp | B4: 1600
A5: supreme_exp | B5: 6400
A6: Jade_Parcels | B6: GlobalStatBuff | C6: 15 | D6: CRIT_RATE | E6: Flat | F6: 10
A7: Dragon_Bread_Noodies | B7: GlobalStatBuff | C7: 30 | D7: CRIT_DMG_RES | E7: Flat | F7: 10
A8: Lamian_Noodies | B8: GlobalStatBuff | C8: 200 | D8: ATK | E8: Flat | F8: 10
A9: Tofu_Soup | B9: GlobalStatBuff | C9: 500 | D9: HP | E9: Flat | F9: 5
A10: Fried_Radish_Balls | B10: GlobalStatBuff | C10: 100 | D10: DEF | E10: Flat | F10: 5
A11: Shirmp_Dumplings | B11: RestoreEnergy | C11: 60
A12: Murshroom_Steamed_Buns | B12: RestoreEnergy | C12: 30

Sheet Weapon
A1: ID | B1: Rare | C1: Type | D1: HP | E1: ATK | F1: GrowthHP | G1: GrowthATK | H1: PassiveID
A2: Nimbus_Cudgel | B2: Legendary | C2: Fighter | D2: 1375 | E2: 225 | F2: 138 | G2: 23 | H2: psv_nimbus_cudgel
A3: Triple_Edged_Blade | B3: Legendary | C3: Fighter | D3: 1375 | E3: 225 | F3: 138 | G3: 23 | H3: psv_triple_edged_blade
A4: Vanguard_Of_Volition | B4: Legendary | C4: Assassin | D4: 875 | E4: 325 | F4: 88 | G4: 33 | H4: psv_vanguard_of_volition
A5: Ninefold_Staff | B5: Rare | C5: Support | D5: 495 | E5: 121 | F5: 50 | G5: 12 | H5: psv_ninefold_staff
A6: Nine_ToolThed_Rake | B6: Legendary | C6: Tanker | D6: 2000 | E6: 100 | F6: 200 | G6: 10 | H6: psv_nine_toothed_rake
A7: Nimbus_Cloud | B7: Rare | C7: Mage | D7: 495 | E7: 121 | F7: 50 | G7: 12 | H7: psv_nimbus_cloud
A8: Sunburst_Spade | B8: Common | C8: Normal | D8: 300 | E8: 40 | F8: 30 | G8: 4 | H8: psv_sunburst_spade
A9: Reincarnation | B9: Epic | C9: ADCarry | D9: 578 | E9: 214 | F9: 58 | G9: 21 | H9: psv_reincarnation
A10: Ennead_spear | B10: Uncommon | C10: Normal | D10: 450 | E10: 60 | F10: 45 | G10: 6 | H10: psv_ennead_spear
A11: Crescent_Axe | B11: Common | C11: Normal | D11: 300 | E11: 40 | F11: 30 | G11: 4 | H11: psv_crescent_axe
A12: Bronze_Hammer | B12: Uncommon | C12: Tanker | D12: 600 | E12: 30 | F12: 60 | G12: 3 | H12: psv_bronze_hammer
A13: Moonlit_Firelfy | B13: Legendary | C13: Mage | D13: 1125 | E13: 275 | F13: 113 | G13: 28 | H13: psv_moonlit_firefly
... A16: Windfire_Wheel | B16: Epic | C16: Assassin | D16: 578 | E16: 214 | F16: 58 | G16: 21 | H16: psv_windfire_wheel
A17: Wooden_Staff | B17: Legendary | C17: Normal | D17: 300 | E17: 40 | F17: 30 | G17: 4
A18: LingLong_Pagoda | B18: Legendary | C18: Tanker | D18: 2200 | E18: 120 | F18: 220 | G18: 12 | H18: psv_linglong_pagoda
A19: Ferrous_Chaos | B19: Legendary | C19: Fighter | D19: 1375 | E19: 225 | F19: 138 | G19: 23 | H19: psv_ferrous_chaos

Sheet Passives
A1: ID | B1: desc_template | C1: Note
A2: psv_nimbus_cudgel | B2: STR_NIMBUS_CUDGEL_SKILL | C2: Tấn công và phòng thủ tăng {0}%. Sau khi tấn công đơn, nếu đánh bại mục tiêu thì điểm hành động tăng {1}%.
A3: psv_triple_edged_blade | B3: STR_TRIPLE_EDGED_BLADE_SKILL | C3: Tăng {0}% Sát Thương Bạo Kích và {1}% Tấn Công. Sau khi thi triển kỹ năng tấn công đơn đánh bại mục tiêu, có {2}% xác suất hiệp hồi chiêu kỹ năng của bản thân -1.
A4: psv_vanguard_of_volition | B4: STR_VANGUARD_OF_VOLITION_SKILL | C4: Tăng {0}% Sát Thương Bạo Kích và {1}% Tấn Công. Khi gây sát thương Bạo Kích, tăng {2}% Điểm Hành Động của bản thân. Sau khi tấn công đơn mục tiêu, nếu mục tiêu còn sống, có {3}% xác suất lập tức tung đòn Đánh Thường để truy kích.
A5: psv_ninefold_staff | B5: STR_NINEFOLD_STAFF_SKILL | C5: Tăng {0}% Tốc Độ. Tăng thêm {1}% hiệu quả cho các kỹ năng Cường Hóa và Hỗ Trợ.
A6: psv_nine_toothed_rake | B6: STR_NINE_TOOLTHED_RAKE_SKILL | C6: Tăng {0}% HP và {0}% Phòng Thủ. Mỗi khi chịu sát thương, Phòng Thủ tăng thêm {1}%, tối đa cộng dồn 5 tầng. Khi đạt 5 tầng, hồi phục 10% HP Tối Đa.
A7: psv_nimbus_cloud | B7: STR_NIMBUS_CLOUD_SKILL | C7: Tăng {0}% Tốc Độ và {1}% Tấn Công. Khi bắt đầu lượt, tăng {2}% Điểm Hành Động của bản thân.
A8: psv_sunburst_spade | B8: STR_SUNBURST_SPADE_SKILL | C8: Tấn công tăng {0}%.
A9: psv_reincarnation | B9: STR_REINCARNATION_SKILL | C9: Tấn công tăng {0}%. Đòn tấn công đơn mục tiêu gây thêm {1}% Sát thương.
A10: psv_ennead_spear | B10: STR_ENNEAD_SPEAR_SKILL | C10: Tỷ lệ bạo kích tăng {0}%.
A11: psv_crescent_axe | B11: STR_CRESCENT_AXE_SKILL | C11: ST Bạo Kích tăng {0}%.
A12: psv_bronze_hammer | B12: STR_BRONZE_HAMMER_SKILL | C12: Phòng thủ tăng {0}%.
... A22: psv_linglong_pagoda | B22: STR_LINGLONG_PAGODA_SKILL | C22: HP Tối Đa tăng {0}%. Đồng thời giảm 15% sát thương nhận vào ở đòn đánh đầu tiên; các đòn tiếp theo có 40% tỉ lệ kích hoạt hiệu ứng [Giảm Sát Thương] (giảm 10% sát thương).
A23: psv_bulldemonking_counter | B23: STR_BULL_COUNTER_NAME | C23: Có 50%, 75%, 100% cơ hội phản kích khi bị đánh thường | D23: STR_BULL_COUNTER_DES
A24: psv_ferrous_chaos | B24: STR_FERROUS_CHAOS_SKILL | C24: Tăng {0}% Tấn Công và {0}% Phòng Thủ. Trạng thái Áp Đảo (HP > 50%) tăng 16% Sát thương Kỹ năng. Trạng thái Huyết Chiến (HP ≤ 50%) nhận 16% Hút Máu tương đương 16% tổng sát thương gây ra.
A25: psv_nezha_ultimate | B25: STR_NEZHA_ULT_PASSIVE | C25: Khi kết liễu kẻ địch bằng chiêu cuối, kích hoạt hiệu ứng [Càn Quét] tấn công 1 kẻ địch khác với 120% ATK.
A26: psv_windfire_wheel | B26: STR_WINDFIRE_WHEEL_SKILL | C26: Tăng {0}% Sát Thương Bạo Kích và {0}% Tấn Công. Khi gây sát thương Bạo Kích, tăng {1}% Điểm Hành Động của bản thân.
A27: psv_thirddragon_major | B27: STR_THIRD_DRAGON_MAJOR_PAS | C27: Bắn cầu băng gây sát thương và làm Tê Tái giảm {0}% Tốc độ trong 2 hiệp.
A28: psv_theboysage_ultimate | B28: STR_THEBOYSAGE_ULTIMATE_PASSIVE | C28: Tuyệt kỹ bỏ qua 30% Phòng Thủ của mục tiêu.

Sheet StaticModifiers
A1: passive_id | B1: stat_type | C1: modify_type | D1: modify_by_upgrade | E1: Note
A2: psv_nimbus_cudgel | B2: ATK | C2: Percent | D2: 10, 15, 20, 25, 30, 35 | E2: Tấn công và phòng thủ tăng {0}%. Sau khi tấn công đơn, nếu đánh bại mục tiêu thì điểm hành động tăng {1}%.
A3: psv_nimbus_cudgel | B3: DEF | C3: Percent | D3: 10, 15, 20, 25, 30, 35 | E3: Tấn công và phòng thủ tăng {0}%. Sau khi tấn công đơn, nếu đánh bại mục tiêu thì điểm hành động tăng {1}%.
A4: psv_ninefold_staff | B4: SPEED | C4: Percent | D4: 6, 8, 10, 12, 15, 20 | E4: Tăng {0}% Tốc Độ. Tăng thêm {1}% hiệu quả cho các kỹ năng Cường Hóa và Hỗ Trợ.
A5: psv_reincarnation | B5: ATK | C5: Percent | D5: 8, 11, 14, 17, 20, 25 | E5: Tấn công tăng {0}%. Đòn tấn công đơn mục tiêu gây thêm {1}% Sát thương.
A6: psv_ennead_spear | B6: CRIT_RATE | C6: Percent | D6: 5, 7.5, 10, 12.5, 16, 20 | E6: Tỷ lệ bạo kích tăng {0}%.
A7: psv_crescent_axe | B7: CRIT_DMG | C7: Percent | D7: 5, 7.5, 10, 12.5, 17,, 21 | E7: ST Bạo Kích tăng {0}%.
A8: psv_bronze_hammer | B8: DEF | C8: Percent | D8: 5, 7.5, 10, 12.5, 16, 20 | E8: Phòng thủ tăng {0}%.
A9: psv_linglong_pagoda | B9: HP | C9: Percent | D9: 15, 20, 25, 30, 35, 40 | E9: HP tối đa tăng {0}%
A10: psv_ferrous_chaos | B10: ATK | C10: Percent | D10: 10, 15, 20, 25, 30, 35 | E10: Tăng {0}% Tấn Công và {0}% Phòng Thủ. Trạng thái Áp Đảo (HP > 50%) tăng 16% Sát thương Kỹ năng. Trạng thái Huyết Chiến (HP ≤ 50%) nhận 16% Hút Máu tương đương 16% tổng sát thương gây ra.
A11: psv_ferrous_chaos | B11: DEF | C11: Percent | D11: 10, 15, 20, 25, 30, 35 | E11: Tăng {0}% Tấn Công và {0}% Phòng Thủ. Trạng thái Áp Đảo (HP > 50%) tăng 16% Sát thương Kỹ năng. Trạng thái Huyết Chiến (HP ≤ 50%) nhận 16% Hút Máu tương đương 16% tổng sát thương gây ra.
A12: psv_windfire_wheel | B12: CRIT_DMG | C12: Percent | D12: 8, 10, 12, 14, 17, 20 | E12: Tăng {0}% Sát Thương Bạo Kích và {0}% Tấn Công. Khi gây sát thương Bạo Kích, tăng {1}% Điểm Hành Động của bản thân.
... A18: psv_vanguard_of_volition | B18: ATK | C18: Percent | D18: 10, 12, 14, 17, 20, 25 | E18: Tăng {0}% Sát Thương Bạo Kích và {1}% Tấn Công. Khi gây sát thương Bạo Kích, tăng {2}% Điểm Hành Động của bản thân. Sau khi tấn công đơn mục tiêu, nếu mục tiêu còn sống, có {3}% xác suất lập tức tung đòn Đánh Thường để truy kích.
A19: psv_nimbus_cloud | B19: SPEED | C19: Percent | D19: 4.0, 5.0, 6.0, 7.0, 8.5, 10.0
A20: psv_nimbus_cloud | B20: ATK | C20: Percent | D20: 5.0, 6.5, 8.0, 10.0, 12.0, 15.0
A21: psv_plantain_fan | B21: CRIT_DMG | C21: Percent | D21: 20.0, 25.0, 30.0, 35.0, 40.0, 50.0
A22: psv_plantain_fan | B22: ATK | C22: Percent | D22: 10.0, 12.0, 14.0, 17.0, 20.0, 25.0
A23: psv_triple_edged_blade | B23: CRIT_DMG | C23: Percent | D23: 30.0, 36.0, 42.0, 48.0, 54.0, 60.0 | E23: Tăng {0}% Sát Thương Bạo Kích và {1}% Tấn Công. Sau khi thi triển kỹ năng tấn công đơn đánh bại mục tiêu, có {2}% xác suất hiệp hồi chiêu kỹ năng của bản thân -1.
A24: psv_triple_edged_blade | B24: ATK | C24: Percent | D24: 10.0, 12.0, 14.0, 17.0, 20.0, 25.0 | E24: Tăng {0}% Sát Thương Bạo Kích và {1}% Tấn Công. Sau khi thi triển kỹ năng tấn công đơn đánh bại mục tiêu, có {2}% xác suất hiệp hồi chiêu kỹ năng của bản thân -1.
A25: psv_moonlit_firefly | B25: SPEED | C25: Percent | D25: 8.0, 10.0, 12.0, 15.0, 18.0, 25.0 | E25: Tăng {0}% Tốc Độ và {1}% Tấn Công. Tăng thêm {2}% hiệu quả cho các kỹ năng Cường Hóa và Hỗ Trợ.
A26: psv_moonlit_firefly | B26: ATK | C26: Percent | D26: 10.0, 12.0, 14.0, 17.0, 20.0, 25.0 | E26: Tăng {0}% Tốc Độ và {1}% Tấn Công. Tăng thêm {2}% hiệu quả cho các kỹ năng Cường Hóa và Hỗ Trợ.
A27: psv_wings_of_phoenix | B27: HP | C27: Percent | D27: 15.0, 18.0, 21.0, 25.0, 30.0, 40.0 | E27: Tăng {0}% HP và {1}% Phòng Thủ. Tăng thêm {2}% hiệu quả cho các kỹ năng Hồi Máu.
A28: psv_wings_of_phoenix | B28: DEF | C28: Percent | D28: 10.0, 12.0, 14.0, 17.0, 20.0, 25.0 | E28: Tăng {0}% HP và {1}% Phòng Thủ. Tăng thêm {2}% hiệu quả cho các kỹ năng Hồi Máu.
A29: psv_thirddragon_major | B29: ATK | C29: Percent | D29: 10, 15, 20, 25, 30, 35 | E29: Tăng {0}% ATK

Sheet CombatEvents
A1: passive_id | B1: event_type | C1: effect_id | D1: modify_by_upgrade | E1: condition_filter | F1: effect_param | G1: internal_cooldown | H1: target | I1: Note
A2: psv_nimbus_cudgel | B2: OnAfterDealDamage | C2: Eff_Action_Point_Boost | D2: 20, 25, 30, 35, 40, 50 | E2: SingleTarget, TargetDead | F2: 0 | H2: self | I2: Tấn công và phòng thủ tăng {0}%. Sau khi tấn công đơn, nếu đánh bại mục tiêu thì điểm hành động tăng {1}%.
A3: psv_triple_edged_blade | B3: OnAfterDealDamage | C3: Eff_Reduce_Cooldown | D3: 100.0, 100.0, 100.0, 100.0, 100.0, 100.0 | E3: IsSkill, SingleTarget, TargetDead | F3: 1 | G3: 0 | H3: self | I3: Tăng {0}% Sát Thương Bạo Kích và {1}% Tấn Công. Sau khi thi triển kỹ năng tấn công đơn đánh bại mục tiêu, có {2}% xác suất hiệp hồi chiêu kỹ năng của bản thân -1.
A4: psv_ninefold_staff | B4: OnSkillStart | C4: Eff_Buff_Enhance | D4: 30.0, 35.0, 40.0, 45.0, 50.0, 60.0 | E4: None | F4: 0 | G4: 0 | H4: self | I4: Tăng {0}% Tốc Độ. Tăng thêm {1}% hiệu quả cho các kỹ năng Cường Hóa và Hỗ Trợ.
A5: psv_reincarnation | B5: OnBeforeDealDamage | C5: Eff_IncreaseAttack | D5: 10.0, 13.0, 16.0, 19.0, 22.0, 25.0 | E5: SingleTarget | F5: 0 | G5: 0 | H5: self | I5: Tấn công tăng {0}%. Đòn tấn công đơn mục tiêu gây thêm {1}% Sát thương.
A6: psv_sunwukong_major | B6: OnAfterDealDamage | C6: Eff_Lifesteal | D6: 20, 25, 30, 30, 30, 30 | E6: MajorSkill | F6: 0 | G6: 0 | H6: self | I6: Kỹ năng Major hút máu 25%
A7: psv_erlangshen_major | B7: OnBeforeDealDamage | C7: Eff_IncreaseCritDmg | D7: 60, 80, 100, 100, 100, 100 | E7: MajorSkill | F7: 0 | G7: 0 | H7: self | I7: Kỹ năng Major tăng 100% Crit DMG
A8: psv_lijing_base | B8: OnAfterDealDamage | C8: Eff_AddShield | D8: 5, 5, 5, 5, 5, 5 | E8: BasicAttack | F8: 5 | G8: 0 | H8: self | I8: Đánh thường nhận khiên 5% Max HP (max 5 tầng)
A9: psv_lijing_ultimate | B9: OnBeforeDealDamage | C9: Eff_HPScalingDamage | D9: 30, 30, 30, 30, 30, 30 | E9: UltimateSkill | F9: 0 | G9: 0 | H9: self | I9: Tuyệt kỹ nộ tăng 30% Max HP vào Base Damage
A10: psv_erlangshen_ultimate | B10: OnBeforeDealDamage | C10: Eff_ArmorPenetration | D10: 30, 30, 30, 30, 30, 30 | E10: UltimateSkill | F10: 0 | G10: 0 | H10: self | I10: Tuyệt kỹ tăng 30% Xuyên Giáp
A11: psv_sunwukong_ultiamte | B11: OnAfterDealDamage | C11: Eff_ReduceDefense | D11: 15, 20, 25, 25, 25, 25 | E11: UltimateSkill | F11: 0 | G11: 0 | H11: enemy | I11: Tuyệt kỹ giảm 25% DEF mục tiêu
A12: psv_bulldemonking_counter | B12: OnTakeDamage | C12: Eff_CounterAttack | D12: 50, 75, 100, 100, 100, 100 | E12: BasicAttack | F12: 100 | G12: 0 | H12: enemy | I12: Có 50%, 75%, 100% cơ hội phản kích khi bị đánh thường, gây 100% ATK
A13: psv_ferrous_chaos | B13: OnBeforeDealDamage | C13: Eff_IncreaseAttack | D13: 16, 16, 16, 16, 16, 16 | E13: IsSkill, HP_Above_50 | F13: 0 | G13: 0 | H13: self | I13: Trạng thái Áp Đảo (HP > 50%) tăng 16% Sát thương Kỹ năng
A14: psv_ferrous_chaos | B14: OnAfterDealDamage | C14: Eff_Lifesteal | D14: 16, 16, 16, 16, 16, 16 | E14: HP_BelowOrEqual_50 | F14: 0 | G14: 0 | H14: self | I14: Trạng thái Huyết Chiến (HP ≤ 50%) nhận 16% Hút Máu
... A19: psv_vanguard_of_volition | B19: OnAfterSkillExecute | C19: Eff_FollowUp_BasicAttack | D19: 50.0, 60.0, 70.0, 80.0, 90.0, 100.0 | E19: SingleTarget, TargetAlive | F19: 0 | G19: 0 | H19: self | I19: Tăng {0}% Sát Thương Bạo Kích và {1}% Tấn Công. Khi gây sát thương Bạo Kích, tăng {2}% Điểm Hành Động của bản thân. Sau khi tấn công đơn mục tiêu, nếu mục tiêu còn sống, có {3}% xác suất lập tức tung đòn Đánh Thường để truy kích.
A20: psv_nimbus_cloud | B20: OnTurnStart | C20: Eff_Action_Point_Boost | D20: 10.0, 12.0, 14.0, 16.0, 18.0, 20.0 | F20: 0 | G20: 0 | H20: self | I20: Tăng {0}% Tốc Độ và {1}% Tấn Công. Khi bắt đầu lượt, tăng {2}% Điểm Hành Động của bản thân.
A21: psv_plantain_fan | B21: OnAfterDealDamage | C21: Eff_ReduceDefense | D21: 15.0, 18.0, 21.0, 24.0, 27.0, 30.0 | E21: IsSkill | F21: 60 | G21: 0 | H21: enemy | I21: Tăng {0}% Sát Thương Bạo Kích và {1}% Tấn Công. Đòn tấn công kỹ năng có 60% xác suất giảm {2}% Phòng Thủ của mục tiêu trong 2 hiệp và gây thêm {3}% Sát Thương lên kẻ địch đang chịu hiệu ứng bất lợi.
A22: psv_plantain_fan | B22: OnBeforeDealDamage | C22: Eff_DamageBonus | D22: 15.0, 18.0, 21.0, 24.0, 27.0, 30.0 | E22: TargetHasDebuff | F22: 0 | G22: 0 | H22: self | I22: Tăng {0}% Sát Thương Bạo Kích và {1}% Tấn Công. Đòn tấn công kỹ năng có 60% xác suất giảm {2}% Phòng Thủ của mục tiêu trong 2 hiệp và gây thêm {3}% Sát Thương lên kẻ địch đang chịu hiệu ứng bất lợi.
A23: psv_moonlit_firefly | B23: OnBeforeDealDamage | C23: Eff_Buff_Enhance | D23: 40.0, 50.0, 60.0, 70.0, 80.0, 100.0 | E23: None | F23: 0 | G23: 0 | H23: self | I23: Tăng {0}% Tốc Độ và {1}% Tấn Công. Tăng thêm {2}% hiệu quả cho các kỹ năng Cường Hóa và Hỗ Trợ.
A24: psv_wings_of_phoenix | B24: OnBeforeDealDamage | C24: Eff_Buff_Enhance | D24: 30.0, 40.0, 50.0, 60.0, 70.0, 80.0 | E24: None | F24: 0 | G24: 0 | H24: self | I24: Tăng {0}% HP và {1}% Phòng Thủ. Tăng thêm {2}% hiệu quả cho các kỹ năng Hồi Máu.
A25: psv_thirddragon_major | B25: OnAfterDealDamage | C25: EFF_DefSpd_def | D25: -20, -25, -30, -35, -40, -50 | E25: MajorSkill | F25: 0 | H25: target | I25: Làm giảm tốc độ kẻ địch
A26: psv_theboysage_ultimate | B26: OnBeforeDealDamage | C26: Eff_ArmorPenetration | D26: 30, 30, 30, 30, 30, 30 | E26: UltimateSkill | F26: 0 | G26: 0 | H26: self | I26: Tuyệt kỹ bỏ qua 30% Phòng Thủ của mục tiêu

Sheet EffectConfig
A1: ID | B1: Name | C1: Des | D1: Type | E1: TargetStat | F1: ModifyType | G1: Duration | H1: Value | I1: MaxStack
A2: EFF_Posion_def | B2: EFF_POSION_NAME | C2: EFF_POSION_DES | D2: Poison | E2: None | F2: None | G2: 3 | H2: 5 | I2: 1
A3: EFF_Stun_def | B3: DEBUFF_STUN_NAME | C3: DEBUFF_STUN_DES | D3: Stun | E3: None | F3: None | G3: 1 | H3: 100 | I3: 1
A4: EFF_BufATK_def | B4: BUFF_ATTACK_NAME | C4: BUFF_ATTACK_DES | D4: StatBuff | E4: ATK | F4: Flat | G4: 3 | H4: 600 | I4: 1
A5: EFF_BufDEF_def | B5: BUFF_DEF_NAME | C5: BUFF_DEF_DES | D5: StatBuff | E5: DEF | F5: Percent | G5: 2 | H5: 20 | I5: 1
A6: EFF_BufSpd_def | B6: BUFF_SPEED_NAME | C6: BUFF_SPEED_DES | D6: StatBuff | E6: SPEED | F6: Percent | G6: 2 | H6: 20 | I6: 1
A7: EFF_DefSpd_def | B7: DEBUFF_SPEED_NAME | C7: DEBUFF_SPEED_DES | D7: StatDebuff | E7: SPEED | F7: Percent | G7: 2 | H7: -20 | I7: 1
A8: EFF_ResetDef | B8: RESIST_DEBUFF_NAME | C8: RESIST_DEBUFF_DES | D8: ResetDebuff | E8: None | F8: None | G8: 1 | H8: 0 | I8: 1
A9: EFF_Frozen_def | B9: DEBUFF_FRONZEN_NAME | C9: DEBUFF_FRONZEN_DES | D9: Frozen | E9: None | F9: None | G9: 2 | H9: 100 | I9: 1
A10: EFF_Bull_Buff_ATK | B10: BUFF_ATTACK_NAME | C10: BUFF_ATTACK_DES | D10: StatBuff | E10: ATK | F10: Percent | G10: 3 | H10: 30 | I10: 1
A11: EFF_Bull_Poison | B11: EFF_POSION_NAME | C11: EFF_POSION_DES | D11: Poison | E11: None | F11: Percent | G11: 3 | H11: 8 | I11: 1
A12: EFF_Zhu_DefShred | B12: DEBUFF_DEF_NAME | C12: DEBUFF_DEF_DES | D12: StatDebuff | E12: DEF | F12: Percent | G12: 2 | H12: -20 | I12: 1
A13: EFF_Sha_Buff_DEF | B13: BUFF_DEF_NAME | C13: BUFF_DEF_DES | D13: StatBuff | E13: DEF | F13: Percent | G13: 2 | H13: 25 | I13: 1
... A17: EFF_Burn_def | B17: EFF_BURN_NAME | C17: EFF_BURN_DES | D17: Burn | E17: None | F17: Percent | G17: 2 | H17: 8 | I17: 3

Sheet Armor
A1: ID | B1: Part | C1: SetArmor | D1: Rare | E1: main_stat_type | F1: main_stat_valuie | G1: modifier_type | H1: substat_pool_id
A2: Armor01_Helmet | B2: Helmet | C2: Armor01 | D2: Legendary | E2: hp | F2: 500 | G2: Flat | H2: Warrior_Pool
A3: Armor02_Helmet | B3: Helmet | C3: Armor02 | D3: Rare | E3: hp | F3: 500 | G3: Flat | H3: Warrior_Pool
A4: Armor03_Helmet | B4: Helmet | C4: Armor03 | D4: Uncommon | E4: hp | F4: 500 | G4: Flat | H4: Tanker_Pool
A5: Armor04_Helmet | B5: Helmet | C5: Armor04 | D5: Epic | E5: hp | F5: 500 | G5: Flat | H5: Tanker_Pool
A6: Armor05_Helmet | B6: Helmet | C6: Armor05 | D6: Common | E6: hp | F6: 500 | G6: Flat | H6: Warrior_Pool
A7: Armor06_Helmet | B7: Helmet | C7: Armor06 | D7: Epic | E7: hp | F7: 500 | G7: Flat | H7: Assassin_Pool
A8: Armor07_Helmet | B8: Helmet | C8: Armor07 | D8: Legendary | E8: hp | F8: 500 | G8: Flat | H8: Assassin_Pool
A9: Armor08_Helmet | B9: Helmet | C9: Armor08 | D9: Legendary | E9: hp | F9: 500 | G9: Flat | H9: Warrior_Pool
A10: Armor01_Chestplate | B10: Chestplate | C10: Armor01 | D10: Legendary | E10: def | F10: 40 | G10: Flat | H10: Warrior_Pool
A11: Armor02_Chestplate | B11: Chestplate | C11: Armor02 | D11: Rare | E11: def | F11: 40 | G11: Flat | H11: Warrior_Pool
A12: Armor03_Chestplate | B12: Chestplate | C12: Armor03 | D12: Uncommon | E12: def | F12: 40 | G12: Flat | H12: Tanker_Pool
A13: Armor04_Chestplate | B13: Chestplate | C13: Armor04 | D13: Epic | E13: def | F13: 40 | G13: Flat | H13: Tanker_Pool
... A33: Armor08_Boots | B33: Boots | C33: Armor08 | D33: Legendary | E33: speed | F33: 3 | G33: Flat | H33: Warrior_Pool
A34: Armor01_Belt | B34: Belt | C34: Armor01 | D34: Legendary | E34: hp | F34: 3.5 | G34: Percent | H34: Warrior_Pool
A35: Armor02_Belt | B35: Belt | C35: Armor02 | D35: Rare | E35: hp | F35: 3.5 | G35: Percent | H35: Warrior_Pool
A36: Armor03_Belt | B36: Belt | C36: Armor03 | D36: Uncommon | E36: hp | F36: 3.5 | G36: Percent | H36: Tanker_Pool
A37: Armor04_Belt | B37: Belt | C37: Armor04 | D37: Epic | E37: hp | F37: 3.5 | G37: Percent | H37: Tanker_Pool
A38: Armor05_Belt | B38: Belt | C38: Armor05 | D38: Common | E38: hp | F38: 3.5 | G38: Percent | H38: Warrior_Pool
A39: Armor06_Belt | B39: Belt | C39: Armor06 | D39: Epic | E39: hp | F39: 3.5 | G39: Percent | H39: Assassin_Pool
A40: Armor07_Belt | B40: Belt | C40: Armor07 | D40: Legendary | E40: hp | F40: 3.5 | G40: Percent | H40: Assassin_Pool
A41: Armor08_Belt | B41: Belt | C41: Armor08 | D41: Legendary | E41: hp | F41: 3.5 | G41: Percent | H41: Warrior_Pool
A42: Armor01_Ring | B42: Ring | C42: Armor01 | D42: Legendary | E42: crit_rate | F42: 5 | G42: Flat | H42: Warrior_Pool
A43: Armor02_Ring | B43: Ring | C43: Armor02 | D43: Rare | E43: crit_rate | F43: 5 | G43: Flat | H43: Warrior_Pool
A44: Armor03_Ring | B44: Ring | C44: Armor03 | D44: Uncommon | E44: crit_rate | F44: 5 | G44: Flat | H44: Tanker_Pool
A45: Armor04_Ring | B45: Ring | C45: Armor04 | D45: Epic | E45: crit_rate | F45: 5 | G45: Flat | H45: Tanker_Pool
A46: Armor05_Ring | B46: Ring | C46: Armor05 | D46: Common | E46: crit_rate | F46: 5 | G46: Flat | H46: Warrior_Pool
A47: Armor06_Ring | B47: Ring | C47: Armor06 | D47: Epic | E47: crit_rate | F47: 5 | G47: Flat | H47: Assassin_Pool
A48: Armor07_Ring | B48: Ring | C48: Armor07 | D48: Legendary | E48: crit_rate | F48: 5 | G48: Flat | H48: Assassin_Pool
A49: Armor08_Ring | B49: Ring | C49: Armor08 | D49: Legendary | E49: crit_rate | F49: 5 | G49: Flat | H49: Warrior_Pool

Sheet SubstatPool
A1: ID | B1: StatType | C1: Min | D1: Max | E1: Modifier_Type | F1: Weight
A2: Warrior_Pool | B2: HP | C2: 100 | D2: 500 | E2: Flat | F2: 100
A3: Warrior_Pool | B3: ATK | C3: 15 | D3: 75 | E3: Flat | F3: 100
A4: Warrior_Pool | B4: DEF | C4: 10 | D4: 50 | E4: Flat | F4: 100
A5: Warrior_Pool | B5: HP | C5: 2 | D5: 6 | E5: Percent | F5: 60
A6: Warrior_Pool | B6: ATK | C6: 2 | D6: 6 | E6: Percent | F6: 60
A7: Warrior_Pool | B7: DEF | C7: 2 | D7: 6 | E7: Percent | F7: 60
A8: Warrior_Pool | B8: PENETRATION | C8: 0.8 | D8: 2 | E8: Percent | F8: 75
A9: Warrior_Pool | B9: CRIT_RATE | C9: 2 | D9: 5 | E9: Percent | F9: 35
A10: Warrior_Pool | B10: CRIT_DMG | C10: 5 | D10: 12 | E10: Percent | F10: 30
A11: Warrior_Pool | B11: DEF_SHRED | C11: 8 | D11: 24 | E11: Flat | F11: 25
A12: Warrior_Pool | B12: SPEED | C12: 1 | D12: 4 | E12: Flat | F12: 25
A13: Warrior_Pool | B13: CRIT_DMG_RES | C13: 2 | D13: 5 | E13: Percent | F13: 20
... A26: Assassin_Pool | B26: SPEED | C26: 2 | D26: 5 | E26: Flat | F26: 35

Sheet SetBonusConfig
A1: ID | B1: Name | C1: Pieces_Required | D1: Bonus_Stat_Type | E1: Bonus_Value | F1: Modifier_Type
A2: Armor01 | B2: STR_ARMOR_01 | C2: 6 | D2: atk, crit_dmg | E2: 20, 15 | F2: Percent, Percent
A3: Armor02 | B3: STR_ARMOR_02 | C3: 6 | D3: speed, hp | E3: 10, 10 | F3: Percent, Percent
A4: Armor03 | B4: STR_ARMOR_03 | C4: 6 | D4: hp | E4: 20 | F4: Percent
A5: Armor04 | B5: STR_ARMOR_04 | C5: 6 | D5: hp, def | E5: 10, 10 | F5: Percent, Percent
A6: Armor05 | B6: STR_ARMOR_05 | C6: 6 | D6: atk, hp | E6: 8, 8 | F6: Percent, Percent
A7: Armor06 | B7: STR_ARMOR_06 | C7: 6 | D7: atk, crit_dmg | E7: 15, 15 | F7: Percent, Percent
A8: Armor07 | B8: STR_ARMOR_07 | C8: 6 | D8: crit_rate, crit_dmg | E8: 10, 20 | F8: Percent, Percent
A9: Armor08 | B9: STR_ARMOR_08 | C9: 6 | D9: atk, penetration | E9: 12, 10 | F9: Percent, Percent

Sheet Character
A1: ID | B1: Name | C1: Rare | D1: Type | E1: Class | F1: Base | G1: Major | H1: Ultimate
A2: SunWukong | B2: STR_SUN_WUKONG | C2: UR | D2: Fighter | E2: Character | F2: SunWukong_B | G2: SunWukong_M | H2: SunWukong_U
A3: TangSanZang | B3: STR_TANG_SANZANG | C3: R | D3: Mage | E3: Character | F3: TangSanZang_B | G3: TangSanZang_M | H3: TangSanZang_U
A4: ZhuBaJie | B4: STR_ZHU_BAIJE | C4: SR | D4: Tanker | E4: Character | F4: ZhuBaJie_B | G4: ZhuBaJie_M | H4: ZhuBaJie_U
A5: ShaWujing | B5: STR_SHA_WUJING | C5: SR | D5: Tanker | E5: Character | F5: ShaWujing_B | G5: ShaWujing_M | H5: ShaWujing_U
A6: DragonKing | B6: STR_DRAGON_KING_EATERN_SEA | C6: SR | D6: Support | E6: Character | F6: DragonKing_B | G6: DragonKing_M | H6: DragonKing_U
A7: ThirdPrinceNezha | B7: STR_THIRD_PRINCE_NEZHA | C7: SSR | D7: Assassin | E7: Character | F7: ThirdPrinceNezha_B | G7: ThirdPrinceNezha_M | H7: ThirdPrinceNezha_U
A8: LittleWhiteDragon | B8: STR_LITTLE_WHITE_DRAGON | C8: R | D8: ADCarry | E8: Character | F8: LittleWhiteDragon_B | G8: LittleWhiteDragon_M | H8: LittleWhiteDragon_U
A9: BullDemonKing | B9: STR_BULL_DEMON_KING | C9: SSR | D9: Tanker | E9: Character | F9: BullDemonKing_B | G9: BullDemonKing_M | H9: BullDemonKing_U
A10: ErlangShen | B10: STR_ERLANG_SHEN_YANG_JIAN | C10: UR | D10: Fighter | E10: Character | F10: ErlangShen_B | G10: ErlangShen_M | H10: ErlangShen_U
A11: GuanyinBodhisattva | B11: STR_GUANYIN_BODHISATTVA | C11: UR | D11: Mage | E11: Character | F11: GuanyinBodhisattva_B | G11: GuanyinBodhisattva_M | H11: GuanyinBodhisattva_U
A12: VanguardTiger | B12: STR_VANGUARD_TIGER | C12: R | D12: Fighter | E12: Boss | F12: VanguardTiger_B | G12: None_Skill | H12: None_Skill
... A32: ThirdDragonPrince | B32: STR_THIRD_DRAGON_PRINCE | C32: UR | D32: Fighter | E32: Boss | F32: ThirdDragonPrince_B | G32: ThirdDragonPrince_M | H32: ThirdDragonPrince_U

Sheet CharacterStat
A1: ID | B1: Rare | C1: Type | D1: Class | E1: Stat_Bias | F1: hp | G1: atk | H1: def | I1: speed | J1: def_shred | K1: crit_rare | L1: crit_dmg | M1: penetration | N1: crit_dmg_res
A2: SunWukong | B2: =Character!C2 -> UR | C2: =Character!D2 -> Fighter | D2: =Character!E2 -> Character | E2: Offensive | F2: =ROUND(VLOOKUP(C2, Stat_Matrix!$E$2:$N$7, 2, FALSE) * VLOOKUP(B2, Stat_Matrix!$A$2:$B$5, 2, FALSE) * VLOOKUP(IF(ISBLANK(D2), "Character", D2), Stat_Matrix!$AA$2:$AD$4, 2, FALSE) * VLOOKUP(IF(ISBLANK(E2), "Balanced", E2), Stat_Matrix!$AG$2:$AP$6, 2, FALSE), 0) -> 4441 | G2: =ROUND(VLOOKUP(C2, Stat_Matrix!$E$2:$N$7, 3, FALSE) * VLOOKUP(B2, Stat_Matrix!$A$2:$B$5, 2, FALSE) * VLOOKUP(IF(ISBLANK(D2), "Character", D2), Stat_Matrix!$AA$2:$AD$4, 3, FALSE) * VLOOKUP(IF(ISBLANK(E2), "Balanced", E2), Stat_Matrix!$AG$2:$AP$6, 3, FALSE), 0) -> 3086 | H2: =ROUND(VLOOKUP(C2, Stat_Matrix!$E$2:$N$7, 4, FALSE) * VLOOKUP(B2, Stat_Matrix!$A$2:$B$5, 2, FALSE) * VLOOKUP(IF(ISBLANK(D2), "Character", D2), Stat_Matrix!$AA$2:$AD$4, 4, FALSE) * VLOOKUP(IF(ISBLANK(E2), "Balanced", E2), Stat_Matrix!$AG$2:$AP$6, 4, FALSE), 0) -> 444 | I2: =VLOOKUP(C2, Stat_Matrix!$E$2:$N$7, 5, FALSE) + (VLOOKUP(B2, Stat_Matrix!$A$2:$C$5, 3, FALSE) * VLOOKUP(C2, Stat_Matrix!$P$2:$Y$7, 5, FALSE)) + VLOOKUP(IF(ISBLANK(E2), "Balanced", E2), Stat_Matrix!$AG$2:$AP$6, 5, FALSE) -> 96 | J2: =VLOOKUP(C2, Stat_Matrix!$E$2:$N$7, 8, FALSE) + (VLOOKUP(B2, Stat_Matrix!$A$2:$C$5, 3, FALSE) * VLOOKUP(C2, Stat_Matrix!$P$2:$Y$7, 8, FALSE)) + VLOOKUP(IF(ISBLANK(E2), "Balanced", E2), Stat_Matrix!$AG$2:$AP$6, 8, FALSE) -> 16 | K2: =VLOOKUP(C2, Stat_Matrix!$E$2:$N$7, 6, FALSE) + (VLOOKUP(B2, Stat_Matrix!$A$2:$C$5, 3, FALSE) * VLOOKUP(C2, Stat_Matrix!$P$2:$Y$7, 6, FALSE)) + VLOOKUP(IF(ISBLANK(E2), "Balanced", E2), Stat_Matrix!$AG$2:$AP$6, 6, FALSE) -> 10 | L2: =VLOOKUP(C2, Stat_Matrix!$E$2:$N$7, 7, FALSE) + (VLOOKUP(B2, Stat_Matrix!$A$2:$C$5, 3, FALSE) * VLOOKUP(C2, Stat_Matrix!$P$2:$Y$7, 7, FALSE)) + VLOOKUP(IF(ISBLANK(E2), "Balanced", E2), Stat_Matrix!$AG$2:$AP$6, 7, FALSE) -> 22 | M2: =VLOOKUP(C2, Stat_Matrix!$E$2:$N$7, 9, FALSE) + (VLOOKUP(B2, Stat_Matrix!$A$2:$C$5, 3, FALSE) * VLOOKUP(C2, Stat_Matrix!$P$2:$Y$7, 9, FALSE)) + VLOOKUP(IF(ISBLANK(E2), "Balanced", E2), Stat_Matrix!$AG$2:$AP$6, 9, FALSE) -> 5 | N2: =VLOOKUP(C2, Stat_Matrix!$E$2:$N$7, 10, FALSE) + (VLOOKUP(B2, Stat_Matrix!$A$2:$C$5, 3, FALSE) * VLOOKUP(C2, Stat_Matrix!$P$2:$Y$7, 10, FALSE) + VLOOKUP(IF(ISBLANK(D2), "Character", D2), Stat_Matrix!$AA$2:$AE$4, 5, FALSE) + VLOOKUP(IF(ISBLANK(E2), "Balanced", E2), Stat_Matrix!$AG$2:$AP$6, 10, FALSE)) -> 0
A3: TangSanZang | B3: =Character!C3 -> R | C3: =Character!D3 -> Mage | D3: =Character!E3 -> Character | E3: Balanced | F3: =ROUND(VLOOKUP(C3, Stat_Matrix!$E$2:$N$7, 2, FALSE) * VLOOKUP(B3, Stat_Matrix!$A$2:$B$5, 2, FALSE) * VLOOKUP(IF(ISBLANK(D3), "Character", D3), Stat_Matrix!$AA$2:$AD$4, 2, FALSE) * VLOOKUP(IF(ISBLANK(E3), "Balanced", E3), Stat_Matrix!$AG$2:$AP$6, 2, FALSE), 0) -> 2250 | G3: =ROUND(VLOOKUP(C3, Stat_Matrix!$E$2:$N$7, 3, FALSE) * VLOOKUP(B3, Stat_Matrix!$A$2:$B$5, 2, FALSE) * VLOOKUP(IF(ISBLANK(D3), "Character", D3), Stat_Matrix!$AA$2:$AD$4, 3, FALSE) * VLOOKUP(IF(ISBLANK(E3), "Balanced", E3), Stat_Matrix!$AG$2:$AP$6, 3, FALSE), 0) -> 2100 | H3: =ROUND(VLOOKUP(C3, Stat_Matrix!$E$2:$N$7, 4, FALSE) * VLOOKUP(B3, Stat_Matrix!$A$2:$B$5, 2, FALSE) * VLOOKUP(IF(ISBLANK(D3), "Character", D3), Stat_Matrix!$AA$2:$AD$4, 4, FALSE) * VLOOKUP(IF(ISBLANK(E3), "Balanced", E3), Stat_Matrix!$AG$2:$AP$6, 4, FALSE), 0) -> 210 | I3: =VLOOKUP(C3, Stat_Matrix!$E$2:$N$7, 5, FALSE) + (VLOOKUP(B3, Stat_Matrix!$A$2:$C$5, 3, FALSE) * VLOOKUP(C3, Stat_Matrix!$P$2:$Y$7, 5, FALSE)) + VLOOKUP(IF(ISBLANK(E3), "Balanced", E3), Stat_Matrix!$AG$2:$AP$6, 5, FALSE) -> 95 | J3: =VLOOKUP(C3, Stat_Matrix!$E$2:$N$7, 8, FALSE) + (VLOOKUP(B3, Stat_Matrix!$A$2:$C$5, 3, FALSE) * VLOOKUP(C3, Stat_Matrix!$P$2:$Y$7, 8, FALSE)) + VLOOKUP(IF(ISBLANK(E3), "Balanced", E3), Stat_Matrix!$AG$2:$AP$6, 8, FALSE) -> 0 | K3: =VLOOKUP(C3, Stat_Matrix!$E$2:$N$7, 6, FALSE) + (VLOOKUP(B3, Stat_Matrix!$A$2:$C$5, 3, FALSE) * VLOOKUP(C3, Stat_Matrix!$P$2:$Y$7, 6, FALSE)) + VLOOKUP(IF(ISBLANK(E3), "Balanced", E3), Stat_Matrix!$AG$2:$AP$6, 6, FALSE) -> 5 | L3: =VLOOKUP(C3, Stat_Matrix!$E$2:$N$7, 7, FALSE) + (VLOOKUP(B3, Stat_Matrix!$A$2:$C$5, 3, FALSE) * VLOOKUP(C3, Stat_Matrix!$P$2:$Y$7, 7, FALSE)) + VLOOKUP(IF(ISBLANK(E3), "Balanced", E3), Stat_Matrix!$AG$2:$AP$6, 7, FALSE) -> 10 | M3: =VLOOKUP(C3, Stat_Matrix!$E$2:$N$7, 9, FALSE) + (VLOOKUP(B3, Stat_Matrix!$A$2:$C$5, 3, FALSE) * VLOOKUP(C3, Stat_Matrix!$P$2:$Y$7, 9, FALSE)) + VLOOKUP(IF(ISBLANK(E3), "Balanced", E3), Stat_Matrix!$AG$2:$AP$6, 9, FALSE) -> 5 | N3: =VLOOKUP(C3, Stat_Matrix!$E$2:$N$7, 10, FALSE) + (VLOOKUP(B3, Stat_Matrix!$A$2:$C$5, 3, FALSE) * VLOOKUP(C3, Stat_Matrix!$P$2:$Y$7, 10, FALSE) + VLOOKUP(IF(ISBLANK(D3), "Character", D3), Stat_Matrix!$AA$2:$AE$4, 5, FALSE) + VLOOKUP(IF(ISBLANK(E3), "Balanced", E3), Stat_Matrix!$AG$2:$AP$6, 10, FALSE)) -> 0
A4: ZhuBaJie | B4: =Character!C4 -> SR | C4: =Character!D4 -> Tanker | D4: =Character!E4 -> Character | E4: Balanced | F4: =ROUND(VLOOKUP(C4, Stat_Matrix!$E$2:$N$7, 2, FALSE) * VLOOKUP(B4, Stat_Matrix!$A$2:$B$5, 2, FALSE) * VLOOKUP(IF(ISBLANK(D4), "Character", D4), Stat_Matrix!$AA$2:$AD$4, 2, FALSE) * VLOOKUP(IF(ISBLANK(E4), "Balanced", E4), Stat_Matrix!$AG$2:$AP$6, 2, FALSE), 0) -> 4800 | G4: =ROUND(VLOOKUP(C4, Stat_Matrix!$E$2:$N$7, 3, FALSE) * VLOOKUP(B4, Stat_Matrix!$A$2:$B$5, 2, FALSE) * VLOOKUP(IF(ISBLANK(D4), "Character", D4), Stat_Matrix!$AA$2:$AD$4, 3, FALSE) * VLOOKUP(IF(ISBLANK(E4), "Balanced", E4), Stat_Matrix!$AG$2:$AP$6, 3, FALSE), 0) -> 1080 | H4: =ROUND(VLOOKUP(C4, Stat_Matrix!$E$2:$N$7, 4, FALSE) * VLOOKUP(B4, Stat_Matrix!$A$2:$B$5, 2, FALSE) * VLOOKUP(IF(ISBLANK(D4), "Character", D4), Stat_Matrix!$AA$2:$AD$4, 4, FALSE) * VLOOKUP(IF(ISBLANK(E4), "Balanced", E4), Stat_Matrix!$AG$2:$AP$6, 4, FALSE), 0) -> 450 | I4: =VLOOKUP(C4, Stat_Matrix!$E$2:$N$7, 5, FALSE) + (VLOOKUP(B4, Stat_Matrix!$A$2:$C$5, 3, FALSE) * VLOOKUP(C4, Stat_Matrix!$P$2:$Y$7, 5, FALSE)) + VLOOKUP(IF(ISBLANK(E4), "Balanced", E4), Stat_Matrix!$AG$2:$AP$6, 5, FALSE) -> 82 | J4: =VLOOKUP(C4, Stat_Matrix!$E$2:$N$7, 8, FALSE) + (VLOOKUP(B4, Stat_Matrix!$A$2:$C$5, 3, FALSE) * VLOOKUP(C4, Stat_Matrix!$P$2:$Y$7, 8, FALSE)) + VLOOKUP(IF(ISBLANK(E4), "Balanced", E4), Stat_Matrix!$AG$2:$AP$6, 8, FALSE) -> 0 | K4: =VLOOKUP(C4, Stat_Matrix!$E$2:$N$7, 6, FALSE) + (VLOOKUP(B4, Stat_Matrix!$A$2:$C$5, 3, FALSE) * VLOOKUP(C4, Stat_Matrix!$P$2:$Y$7, 6, FALSE)) + VLOOKUP(IF(ISBLANK(E4), "Balanced", E4), Stat_Matrix!$AG$2:$AP$6, 6, FALSE) -> 5 | L4: =VLOOKUP(C4, Stat_Matrix!$E$2:$N$7, 7, FALSE) + (VLOOKUP(B4, Stat_Matrix!$A$2:$C$5, 3, FALSE) * VLOOKUP(C4, Stat_Matrix!$P$2:$Y$7, 7, FALSE)) + VLOOKUP(IF(ISBLANK(E4), "Balanced", E4), Stat_Matrix!$AG$2:$AP$6, 7, FALSE) -> 0 | M4: =VLOOKUP(C4, Stat_Matrix!$E$2:$N$7, 9, FALSE) + (VLOOKUP(B4, Stat_Matrix!$A$2:$C$5, 3, FALSE) * VLOOKUP(C4, Stat_Matrix!$P$2:$Y$7, 9, FALSE)) + VLOOKUP(IF(ISBLANK(E4), "Balanced", E4), Stat_Matrix!$AG$2:$AP$6, 9, FALSE) -> 0 | N4: =VLOOKUP(C4, Stat_Matrix!$E$2:$N$7, 10, FALSE) + (VLOOKUP(B4, Stat_Matrix!$A$2:$C$5, 3, FALSE) * VLOOKUP(C4, Stat_Matrix!$P$2:$Y$7, 10, FALSE) + VLOOKUP(IF(ISBLANK(D4), "Character", D4), Stat_Matrix!$AA$2:$AE$4, 5, FALSE) + VLOOKUP(IF(ISBLANK(E4), "Balanced", E4), Stat_Matrix!$AG$2:$AP$6, 10, FALSE)) -> 7
A5: ShaWujing | B5: =Character!C5 -> SR | C5: =Character!D5 -> Tanker | D5: =Character!E5 -> Character | E5: Defensive | F5: =ROUND(VLOOKUP(C5, Stat_Matrix!$E$2:$N$7, 2, FALSE) * VLOOKUP(B5, Stat_Matrix!$A$2:$B$5, 2, FALSE) * VLOOKUP(IF(ISBLANK(D5), "Character", D5), Stat_Matrix!$AA$2:$AD$4, 2, FALSE) * VLOOKUP(IF(ISBLANK(E5), "Balanced", E5), Stat_Matrix!$AG$2:$AP$6, 2, FALSE), 0) -> 5520 | G5: =ROUND(VLOOKUP(C5, Stat_Matrix!$E$2:$N$7, 3, FALSE) * VLOOKUP(B5, Stat_Matrix!$A$2:$B$5, 2, FALSE) * VLOOKUP(IF(ISBLANK(D5), "Character", D5), Stat_Matrix!$AA$2:$AD$4, 3, FALSE) * VLOOKUP(IF(ISBLANK(E5), "Balanced", E5), Stat_Matrix!$AG$2:$AP$6, 3, FALSE), 0) -> 972 | H5: =ROUND(VLOOKUP(C5, Stat_Matrix!$E$2:$N$7, 4, FALSE) * VLOOKUP(B5, Stat_Matrix!$A$2:$B$5, 2, FALSE) * VLOOKUP(IF(ISBLANK(D5), "Character", D5), Stat_Matrix!$AA$2:$AD$4, 4, FALSE) * VLOOKUP(IF(ISBLANK(E5), "Balanced", E5), Stat_Matrix!$AG$2:$AP$6, 4, FALSE), 0) -> 495 | I5: =VLOOKUP(C5, Stat_Matrix!$E$2:$N$7, 5, FALSE) + (VLOOKUP(B5, Stat_Matrix!$A$2:$C$5, 3, FALSE) * VLOOKUP(C5, Stat_Matrix!$P$2:$Y$7, 5, FALSE)) + VLOOKUP(IF(ISBLANK(E5), "Balanced", E5), Stat_Matrix!$AG$2:$AP$6, 5, FALSE) -> 82 | J5: =VLOOKUP(C5, Stat_Matrix!$E$2:$N$7, 8, FALSE) + (VLOOKUP(B5, Stat_Matrix!$A$2:$C$5, 3, FALSE) * VLOOKUP(C5, Stat_Matrix!$P$2:$Y$7, 8, FALSE)) + VLOOKUP(IF(ISBLANK(E5), "Balanced", E5), Stat_Matrix!$AG$2:$AP$6, 8, FALSE) -> 0 | K5: =VLOOKUP(C5, Stat_Matrix!$E$2:$N$7, 6, FALSE) + (VLOOKUP(B5, Stat_Matrix!$A$2:$C$5, 3, FALSE) * VLOOKUP(C5, Stat_Matrix!$P$2:$Y$7, 6, FALSE)) + VLOOKUP(IF(ISBLANK(E5), "Balanced", E5), Stat_Matrix!$AG$2:$AP$6, 6, FALSE) -> 5 | L5: =VLOOKUP(C5, Stat_Matrix!$E$2:$N$7, 7, FALSE) + (VLOOKUP(B5, Stat_Matrix!$A$2:$C$5, 3, FALSE) * VLOOKUP(C5, Stat_Matrix!$P$2:$Y$7, 7, FALSE)) + VLOOKUP(IF(ISBLANK(E5), "Balanced", E5), Stat_Matrix!$AG$2:$AP$6, 7, FALSE) -> 0 | M5: =VLOOKUP(C5, Stat_Matrix!$E$2:$N$7, 9, FALSE) + (VLOOKUP(B5, Stat_Matrix!$A$2:$C$5, 3, FALSE) * VLOOKUP(C5, Stat_Matrix!$P$2:$Y$7, 9, FALSE)) + VLOOKUP(IF(ISBLANK(E5), "Balanced", E5), Stat_Matrix!$AG$2:$AP$6, 9, FALSE) -> 0 | N5: =VLOOKUP(C5, Stat_Matrix!$E$2:$N$7, 10, FALSE) + (VLOOKUP(B5, Stat_Matrix!$A$2:$C$5, 3, FALSE) * VLOOKUP(C5, Stat_Matrix!$P$2:$Y$7, 10, FALSE) + VLOOKUP(IF(ISBLANK(D5), "Character", D5), Stat_Matrix!$AA$2:$AE$4, 5, FALSE) + VLOOKUP(IF(ISBLANK(E5), "Balanced", E5), Stat_Matrix!$AG$2:$AP$6, 10, FALSE)) -> 12
A6: DragonKing | B6: =Character!C6 -> SR | C6: =Character!D6 -> Support | D6: =Character!E6 -> Character | E6: Defensive | F6: =ROUND(VLOOKUP(C6, Stat_Matrix!$E$2:$N$7, 2, FALSE) * VLOOKUP(B6, Stat_Matrix!$A$2:$B$5, 2, FALSE) * VLOOKUP(IF(ISBLANK(D6), "Character", D6), Stat_Matrix!$AA$2:$AD$4, 2, FALSE) * VLOOKUP(IF(ISBLANK(E6), "Balanced", E6), Stat_Matrix!$AG$2:$AP$6, 2, FALSE), 0) -> 4140 | G6: =ROUND(VLOOKUP(C6, Stat_Matrix!$E$2:$N$7, 3, FALSE) * VLOOKUP(B6, Stat_Matrix!$A$2:$B$5, 2, FALSE) * VLOOKUP(IF(ISBLANK(D6), "Character", D6), Stat_Matrix!$AA$2:$AD$4, 3, FALSE) * VLOOKUP(IF(ISBLANK(E6), "Balanced", E6), Stat_Matrix!$AG$2:$AP$6, 3, FALSE), 0) -> 1134 | H6: =ROUND(VLOOKUP(C6, Stat_Matrix!$E$2:$N$7, 4, FALSE) * VLOOKUP(B6, Stat_Matrix!$A$2:$B$5, 2, FALSE) * VLOOKUP(IF(ISBLANK(D6), "Character", D6), Stat_Matrix!$AA$2:$AD$4, 4, FALSE) * VLOOKUP(IF(ISBLANK(E6), "Balanced", E6), Stat_Matrix!$AG$2:$AP$6, 4, FALSE), 0) -> 330 | I6: =VLOOKUP(C6, Stat_Matrix!$E$2:$N$7, 5, FALSE) + (VLOOKUP(B6, Stat_Matrix!$A$2:$C$5, 3, FALSE) * VLOOKUP(C6, Stat_Matrix!$P$2:$Y$7, 5, FALSE)) + VLOOKUP(IF(ISBLANK(E6), "Balanced", E6), Stat_Matrix!$AG$2:$AP$6, 5, FALSE) -> 103 | J6: =VLOOKUP(C6, Stat_Matrix!$E$2:$N$7, 8, FALSE) + (VLOOKUP(B6, Stat_Matrix!$A$2:$C$5, 3, FALSE) * VLOOKUP(C6, Stat_Matrix!$P$2:$Y$7, 8, FALSE)) + VLOOKUP(IF(ISBLANK(E6), "Balanced", E6), Stat_Matrix!$AG$2:$AP$6, 8, FALSE) -> 0 | K6: =VLOOKUP(C6, Stat_Matrix!$E$2:$N$7, 6, FALSE) + (VLOOKUP(B6, Stat_Matrix!$A$2:$C$5, 3, FALSE) * VLOOKUP(C6, Stat_Matrix!$P$2:$Y$7, 6, FALSE)) + VLOOKUP(IF(ISBLANK(E6), "Balanced", E6), Stat_Matrix!$AG$2:$AP$6, 6, FALSE) -> 5 | L6: =VLOOKUP(C6, Stat_Matrix!$E$2:$N$7, 7, FALSE) + (VLOOKUP(B6, Stat_Matrix!$A$2:$C$5, 3, FALSE) * VLOOKUP(C6, Stat_Matrix!$P$2:$Y$7, 7, FALSE)) + VLOOKUP(IF(ISBLANK(E6), "Balanced", E6), Stat_Matrix!$AG$2:$AP$6, 7, FALSE) -> 0 | M6: =VLOOKUP(C6, Stat_Matrix!$E$2:$N$7, 9, FALSE) + (VLOOKUP(B6, Stat_Matrix!$A$2:$C$5, 3, FALSE) * VLOOKUP(C6, Stat_Matrix!$P$2:$Y$7, 9, FALSE)) + VLOOKUP(IF(ISBLANK(E6), "Balanced", E6), Stat_Matrix!$AG$2:$AP$6, 9, FALSE) -> 0 | N6: =VLOOKUP(C6, Stat_Matrix!$E$2:$N$7, 10, FALSE) + (VLOOKUP(B6, Stat_Matrix!$A$2:$C$5, 3, FALSE) * VLOOKUP(C6, Stat_Matrix!$P$2:$Y$7, 10, FALSE) + VLOOKUP(IF(ISBLANK(D6), "Character", D6), Stat_Matrix!$AA$2:$AE$4, 5, FALSE) + VLOOKUP(IF(ISBLANK(E6), "Balanced", E6), Stat_Matrix!$AG$2:$AP$6, 10, FALSE)) -> 10
A7: ThirdPrinceNezha | B7: =Character!C7 -> SSR | C7: =Character!D7 -> Assassin | D7: =Character!E7 -> Character | E7: Offensive | F7: =ROUND(VLOOKUP(C7, Stat_Matrix!$E$2:$N$7, 2, FALSE) * VLOOKUP(B7, Stat_Matrix!$A$2:$B$5, 2, FALSE) * VLOOKUP(IF(ISBLANK(D7), "Character", D7), Stat_Matrix!$AA$2:$AD$4, 2, FALSE) * VLOOKUP(IF(ISBLANK(E7), "Balanced", E7), Stat_Matrix!$AG$2:$AP$6, 2, FALSE), 0) -> 2755 | G7: =ROUND(VLOOKUP(C7, Stat_Matrix!$E$2:$N$7, 3, FALSE) * VLOOKUP(B7, Stat_Matrix!$A$2:$B$5, 2, FALSE) * VLOOKUP(IF(ISBLANK(D7), "Character", D7), Stat_Matrix!$AA$2:$AD$4, 3, FALSE) * VLOOKUP(IF(ISBLANK(E7), "Balanced", E7), Stat_Matrix!$AG$2:$AP$6, 3, FALSE), 0) -> 3589 | H7: =ROUND(VLOOKUP(C7, Stat_Matrix!$E$2:$N$7, 4, FALSE) * VLOOKUP(B7, Stat_Matrix!$A$2:$B$5, 2, FALSE) * VLOOKUP(IF(ISBLANK(D7), "Character", D7), Stat_Matrix!$AA$2:$AD$4, 4, FALSE) * VLOOKUP(IF(ISBLANK(E7), "Balanced", E7), Stat_Matrix!$AG$2:$AP$6, 4, FALSE), 0) -> 276 | I7: =VLOOKUP(C7, Stat_Matrix!$E$2:$N$7, 5, FALSE) + (VLOOKUP(B7, Stat_Matrix!$A$2:$C$5, 3, FALSE) * VLOOKUP(C7, Stat_Matrix!$P$2:$Y$7, 5, FALSE)) + VLOOKUP(IF(ISBLANK(E7), "Balanced", E7), Stat_Matrix!$AG$2:$AP$6, 5, FALSE) -> 111 | J7: =VLOOKUP(C7, Stat_Matrix!$E$2:$N$7, 8, FALSE) + (VLOOKUP(B7, Stat_Matrix!$A$2:$C$5, 3, FALSE) * VLOOKUP(C7, Stat_Matrix!$P$2:$Y$7, 8, FALSE)) + VLOOKUP(IF(ISBLANK(E7), "Balanced", E7), Stat_Matrix!$AG$2:$AP$6, 8, FALSE) -> 21 | K7: =VLOOKUP(C7, Stat_Matrix!$E$2:$N$7, 6, FALSE) + (VLOOKUP(B7, Stat_Matrix!$A$2:$C$5, 3, FALSE) * VLOOKUP(C7, Stat_Matrix!$P$2:$Y$7, 6, FALSE)) + VLOOKUP(IF(ISBLANK(E7), "Balanced", E7), Stat_Matrix!$AG$2:$AP$6, 6, FALSE) -> 16 | L7: =VLOOKUP(C7, Stat_Matrix!$E$2:$N$7, 7, FALSE) + (VLOOKUP(B7, Stat_Matrix!$A$2:$C$5, 3, FALSE) * VLOOKUP(C7, Stat_Matrix!$P$2:$Y$7, 7, FALSE)) + VLOOKUP(IF(ISBLANK(E7), "Balanced", E7), Stat_Matrix!$AG$2:$AP$6, 7, FALSE) -> 29 | M7: =VLOOKUP(C7, Stat_Matrix!$E$2:$N$7, 9, FALSE) + (VLOOKUP(B7, Stat_Matrix!$A$2:$C$5, 3, FALSE) * VLOOKUP(C7, Stat_Matrix!$P$2:$Y$7, 9, FALSE)) + VLOOKUP(IF(ISBLANK(E7), "Balanced", E7), Stat_Matrix!$AG$2:$AP$6, 9, FALSE) -> 9 | N7: =VLOOKUP(C7, Stat_Matrix!$E$2:$N$7, 10, FALSE) + (VLOOKUP(B7, Stat_Matrix!$A$2:$C$5, 3, FALSE) * VLOOKUP(C7, Stat_Matrix!$P$2:$Y$7, 10, FALSE) + VLOOKUP(IF(ISBLANK(D7), "Character", D7), Stat_Matrix!$AA$2:$AE$4, 5, FALSE) + VLOOKUP(IF(ISBLANK(E7), "Balanced", E7), Stat_Matrix!$AG$2:$AP$6, 10, FALSE)) -> 0
A8: LittleWhiteDragon | B8: =Character!C8 -> R | C8: =Character!D8 -> ADCarry | D8: =Character!E8 -> Character | E8: Swift | F8: =ROUND(VLOOKUP(C8, Stat_Matrix!$E$2:$N$7, 2, FALSE) * VLOOKUP(B8, Stat_Matrix!$A$2:$B$5, 2, FALSE) * VLOOKUP(IF(ISBLANK(D8), "Character", D8), Stat_Matrix!$AA$2:$AD$4, 2, FALSE) * VLOOKUP(IF(ISBLANK(E8), "Balanced", E8), Stat_Matrix!$AG$2:$AP$6, 2, FALSE), 0) -> 2090 | G8: =ROUND(VLOOKUP(C8, Stat_Matrix!$E$2:$N$7, 3, FALSE) * VLOOKUP(B8, Stat_Matrix!$A$2:$B$5, 2, FALSE) * VLOOKUP(IF(ISBLANK(D8), "Character", D8), Stat_Matrix!$AA$2:$AD$4, 3, FALSE) * VLOOKUP(IF(ISBLANK(E8), "Balanced", E8), Stat_Matrix!$AG$2:$AP$6, 3, FALSE), 0) -> 2090 | H8: =ROUND(VLOOKUP(C8, Stat_Matrix!$E$2:$N$7, 4, FALSE) * VLOOKUP(B8, Stat_Matrix!$A$2:$B$5, 2, FALSE) * VLOOKUP(IF(ISBLANK(D8), "Character", D8), Stat_Matrix!$AA$2:$AD$4, 4, FALSE) * VLOOKUP(IF(ISBLANK(E8), "Balanced", E8), Stat_Matrix!$AG$2:$AP$6, 4, FALSE), 0) -> 209 | I8: =VLOOKUP(C8, Stat_Matrix!$E$2:$N$7, 5, FALSE) + (VLOOKUP(B8, Stat_Matrix!$A$2:$C$5, 3, FALSE) * VLOOKUP(C8, Stat_Matrix!$P$2:$Y$7, 5, FALSE)) + VLOOKUP(IF(ISBLANK(E8), "Balanced", E8), Stat_Matrix!$AG$2:$AP$6, 5, FALSE) -> 108 | J8: =VLOOKUP(C8, Stat_Matrix!$E$2:$N$7, 8, FALSE) + (VLOOKUP(B8, Stat_Matrix!$A$2:$C$5, 3, FALSE) * VLOOKUP(C8, Stat_Matrix!$P$2:$Y$7, 8, FALSE)) + VLOOKUP(IF(ISBLANK(E8), "Balanced", E8), Stat_Matrix!$AG$2:$AP$6, 8, FALSE) -> 5 | K8: =VLOOKUP(C8, Stat_Matrix!$E$2:$N$7, 6, FALSE) + (VLOOKUP(B8, Stat_Matrix!$A$2:$C$5, 3, FALSE) * VLOOKUP(C8, Stat_Matrix!$P$2:$Y$7, 6, FALSE)) + VLOOKUP(IF(ISBLANK(E8), "Balanced", E8), Stat_Matrix!$AG$2:$AP$6, 6, FALSE) -> 13 | L8: =VLOOKUP(C8, Stat_Matrix!$E$2:$N$7, 7, FALSE) + (VLOOKUP(B8, Stat_Matrix!$A$2:$C$5, 3, FALSE) * VLOOKUP(C8, Stat_Matrix!$P$2:$Y$7, 7, FALSE)) + VLOOKUP(IF(ISBLANK(E8), "Balanced", E8), Stat_Matrix!$AG$2:$AP$6, 7, FALSE) -> 10 | M8: =VLOOKUP(C8, Stat_Matrix!$E$2:$N$7, 9, FALSE) + (VLOOKUP(B8, Stat_Matrix!$A$2:$C$5, 3, FALSE) * VLOOKUP(C8, Stat_Matrix!$P$2:$Y$7, 9, FALSE)) + VLOOKUP(IF(ISBLANK(E8), "Balanced", E8), Stat_Matrix!$AG$2:$AP$6, 9, FALSE) -> 4 | N8: =VLOOKUP(C8, Stat_Matrix!$E$2:$N$7, 10, FALSE) + (VLOOKUP(B8, Stat_Matrix!$A$2:$C$5, 3, FALSE) * VLOOKUP(C8, Stat_Matrix!$P$2:$Y$7, 10, FALSE) + VLOOKUP(IF(ISBLANK(D8), "Character", D8), Stat_Matrix!$AA$2:$AE$4, 5, FALSE) + VLOOKUP(IF(ISBLANK(E8), "Balanced", E8), Stat_Matrix!$AG$2:$AP$6, 10, FALSE)) -> 0
A9: BullDemonKing | B9: =Character!C9 -> SSR | C9: =Character!D9 -> Tanker | D9: =Character!E9 -> Character | E9: Defensive | F9: =ROUND(VLOOKUP(C9, Stat_Matrix!$E$2:$N$7, 2, FALSE) * VLOOKUP(B9, Stat_Matrix!$A$2:$B$5, 2, FALSE) * VLOOKUP(IF(ISBLANK(D9), "Character", D9), Stat_Matrix!$AA$2:$AD$4, 2, FALSE) * VLOOKUP(IF(ISBLANK(E9), "Balanced", E9), Stat_Matrix!$AG$2:$AP$6, 2, FALSE), 0) -> 6670 | G9: =ROUND(VLOOKUP(C9, Stat_Matrix!$E$2:$N$7, 3, FALSE) * VLOOKUP(B9, Stat_Matrix!$A$2:$B$5, 2, FALSE) * VLOOKUP(IF(ISBLANK(D9), "Character", D9), Stat_Matrix!$AA$2:$AD$4, 3, FALSE) * VLOOKUP(IF(ISBLANK(E9), "Balanced", E9), Stat_Matrix!$AG$2:$AP$6, 3, FALSE), 0) -> 1175 | H9: =ROUND(VLOOKUP(C9, Stat_Matrix!$E$2:$N$7, 4, FALSE) * VLOOKUP(B9, Stat_Matrix!$A$2:$B$5, 2, FALSE) * VLOOKUP(IF(ISBLANK(D9), "Character", D9), Stat_Matrix!$AA$2:$AD$4, 4, FALSE) * VLOOKUP(IF(ISBLANK(E9), "Balanced", E9), Stat_Matrix!$AG$2:$AP$6, 4, FALSE), 0) -> 598 | I9: =VLOOKUP(C9, Stat_Matrix!$E$2:$N$7, 5, FALSE) + (VLOOKUP(B9, Stat_Matrix!$A$2:$C$5, 3, FALSE) * VLOOKUP(C9, Stat_Matrix!$P$2:$Y$7, 5, FALSE)) + VLOOKUP(IF(ISBLANK(E9), "Balanced", E9), Stat_Matrix!$AG$2:$AP$6, 5, FALSE) -> 84 | J9: =VLOOKUP(C9, Stat_Matrix!$E$2:$N$7, 8, FALSE) + (VLOOKUP(B9, Stat_Matrix!$A$2:$C$5, 3, FALSE) * VLOOKUP(C9, Stat_Matrix!$P$2:$Y$7, 8, FALSE)) + VLOOKUP(IF(ISBLANK(E9), "Balanced", E9), Stat_Matrix!$AG$2:$AP$6, 8, FALSE) -> 0 | K9: =VLOOKUP(C9, Stat_Matrix!$E$2:$N$7, 6, FALSE) + (VLOOKUP(B9, Stat_Matrix!$A$2:$C$5, 3, FALSE) * VLOOKUP(C9, Stat_Matrix!$P$2:$Y$7, 6, FALSE)) + VLOOKUP(IF(ISBLANK(E9), "Balanced", E9), Stat_Matrix!$AG$2:$AP$6, 6, FALSE) -> 5 | L9: =VLOOKUP(C9, Stat_Matrix!$E$2:$N$7, 7, FALSE) + (VLOOKUP(B9, Stat_Matrix!$A$2:$C$5, 3, FALSE) * VLOOKUP(C9, Stat_Matrix!$P$2:$Y$7, 7, FALSE)) + VLOOKUP(IF(ISBLANK(E9), "Balanced", E9), Stat_Matrix!$AG$2:$AP$6, 7, FALSE) -> 0 | M9: =VLOOKUP(C9, Stat_Matrix!$E$2:$N$7, 9, FALSE) + (VLOOKUP(B9, Stat_Matrix!$A$2:$C$5, 3, FALSE) * VLOOKUP(C9, Stat_Matrix!$P$2:$Y$7, 9, FALSE)) + VLOOKUP(IF(ISBLANK(E9), "Balanced", E9), Stat_Matrix!$AG$2:$AP$6, 9, FALSE) -> 0 | N9: =VLOOKUP(C9, Stat_Matrix!$E$2:$N$7, 10, FALSE) + (VLOOKUP(B9, Stat_Matrix!$A$2:$C$5, 3, FALSE) * VLOOKUP(C9, Stat_Matrix!$P$2:$Y$7, 10, FALSE) + VLOOKUP(IF(ISBLANK(D9), "Character", D9), Stat_Matrix!$AA$2:$AE$4, 5, FALSE) + VLOOKUP(IF(ISBLANK(E9), "Balanced", E9), Stat_Matrix!$AG$2:$AP$6, 10, FALSE)) -> 14
A10: ErlangShen | B10: =Character!C10 -> UR | C10: =Character!D10 -> Fighter | D10: =Character!E10 -> Character | E10: Balanced | F10: =ROUND(VLOOKUP(C10, Stat_Matrix!$E$2:$N$7, 2, FALSE) * VLOOKUP(B10, Stat_Matrix!$A$2:$B$5, 2, FALSE) * VLOOKUP(IF(ISBLANK(D10), "Character", D10), Stat_Matrix!$AA$2:$AD$4, 2, FALSE) * VLOOKUP(IF(ISBLANK(E10), "Balanced", E10), Stat_Matrix!$AG$2:$AP$6, 2, FALSE), 0) -> 4675 | G10: =ROUND(VLOOKUP(C10, Stat_Matrix!$E$2:$N$7, 3, FALSE) * VLOOKUP(B10, Stat_Matrix!$A$2:$B$5, 2, FALSE) * VLOOKUP(IF(ISBLANK(D10), "Character", D10), Stat_Matrix!$AA$2:$AD$4, 3, FALSE) * VLOOKUP(IF(ISBLANK(E10), "Balanced", E10), Stat_Matrix!$AG$2:$AP$6, 3, FALSE), 0) -> 2805 | H10: =ROUND(VLOOKUP(C10, Stat_Matrix!$E$2:$N$7, 4, FALSE) * VLOOKUP(B10, Stat_Matrix!$A$2:$B$5, 2, FALSE) * VLOOKUP(IF(ISBLANK(D10), "Character", D10), Stat_Matrix!$AA$2:$AD$4, 4, FALSE) * VLOOKUP(IF(ISBLANK(E10), "Balanced", E10), Stat_Matrix!$AG$2:$AP$6, 4, FALSE), 0) -> 468 | I10: =VLOOKUP(C10, Stat_Matrix!$E$2:$N$7, 5, FALSE) + (VLOOKUP(B10, Stat_Matrix!$A$2:$C$5, 3, FALSE) * VLOOKUP(C10, Stat_Matrix!$P$2:$Y$7, 5, FALSE)) + VLOOKUP(IF(ISBLANK(E10), "Balanced", E10), Stat_Matrix!$AG$2:$AP$6, 5, FALSE) -> 96 | J10: =VLOOKUP(C10, Stat_Matrix!$E$2:$N$7, 8, FALSE) + (VLOOKUP(B10, Stat_Matrix!$A$2:$C$5, 3, FALSE) * VLOOKUP(C10, Stat_Matrix!$P$2:$Y$7, 8, FALSE)) + VLOOKUP(IF(ISBLANK(E10), "Balanced", E10), Stat_Matrix!$AG$2:$AP$6, 8, FALSE) -> 11 | K10: 12 | L10: =VLOOKUP(C10, Stat_Matrix!$E$2:$N$7, 7, FALSE) + (VLOOKUP(B10, Stat_Matrix!$A$2:$C$5, 3, FALSE) * VLOOKUP(C10, Stat_Matrix!$P$2:$Y$7, 7, FALSE)) + VLOOKUP(IF(ISBLANK(E10), "Balanced", E10), Stat_Matrix!$AG$2:$AP$6, 7, FALSE) -> 14 | M10: =VLOOKUP(C10, Stat_Matrix!$E$2:$N$7, 9, FALSE) + (VLOOKUP(B10, Stat_Matrix!$A$2:$C$5, 3, FALSE) * VLOOKUP(C10, Stat_Matrix!$P$2:$Y$7, 9, FALSE)) + VLOOKUP(IF(ISBLANK(E10), "Balanced", E10), Stat_Matrix!$AG$2:$AP$6, 9, FALSE) -> 5 | N10: =VLOOKUP(C10, Stat_Matrix!$E$2:$N$7, 10, FALSE) + (VLOOKUP(B10, Stat_Matrix!$A$2:$C$5, 3, FALSE) * VLOOKUP(C10, Stat_Matrix!$P$2:$Y$7, 10, FALSE) + VLOOKUP(IF(ISBLANK(D10), "Character", D10), Stat_Matrix!$AA$2:$AE$4, 5, FALSE) + VLOOKUP(IF(ISBLANK(E10), "Balanced", E10), Stat_Matrix!$AG$2:$AP$6, 10, FALSE)) -> 0
A11: GuanyinBodhisattva | B11: =Character!C11 -> UR | C11: =Character!D11 -> Mage | D11: =Character!E11 -> Character | E11: Balanced | F11: =ROUND(VLOOKUP(C11, Stat_Matrix!$E$2:$N$7, 2, FALSE) * VLOOKUP(B11, Stat_Matrix!$A$2:$B$5, 2, FALSE) * VLOOKUP(IF(ISBLANK(D11), "Character", D11), Stat_Matrix!$AA$2:$AD$4, 2, FALSE) * VLOOKUP(IF(ISBLANK(E11), "Balanced", E11), Stat_Matrix!$AG$2:$AP$6, 2, FALSE), 0) -> 3825 | G11: =ROUND(VLOOKUP(C11, Stat_Matrix!$E$2:$N$7, 3, FALSE) * VLOOKUP(B11, Stat_Matrix!$A$2:$B$5, 2, FALSE) * VLOOKUP(IF(ISBLANK(D11), "Character", D11), Stat_Matrix!$AA$2:$AD$4, 3, FALSE) * VLOOKUP(IF(ISBLANK(E11), "Balanced", E11), Stat_Matrix!$AG$2:$AP$6, 3, FALSE), 0) -> 3570 | H11: =ROUND(VLOOKUP(C11, Stat_Matrix!$E$2:$N$7, 4, FALSE) * VLOOKUP(B11, Stat_Matrix!$A$2:$B$5, 2, FALSE) * VLOOKUP(IF(ISBLANK(D11), "Character", D11), Stat_Matrix!$AA$2:$AD$4, 4, FALSE) * VLOOKUP(IF(ISBLANK(E11), "Balanced", E11), Stat_Matrix!$AG$2:$AP$6, 4, FALSE), 0) -> 357 | I11: =VLOOKUP(C11, Stat_Matrix!$E$2:$N$7, 5, FALSE) + (VLOOKUP(B11, Stat_Matrix!$A$2:$C$5, 3, FALSE) * VLOOKUP(C11, Stat_Matrix!$P$2:$Y$7, 5, FALSE)) + VLOOKUP(IF(ISBLANK(E11), "Balanced", E11), Stat_Matrix!$AG$2:$AP$6, 5, FALSE) -> 101 | J11: =VLOOKUP(C11, Stat_Matrix!$E$2:$N$7, 8, FALSE) + (VLOOKUP(B11, Stat_Matrix!$A$2:$C$5, 3, FALSE) * VLOOKUP(C11, Stat_Matrix!$P$2:$Y$7, 8, FALSE)) + VLOOKUP(IF(ISBLANK(E11), "Balanced", E11), Stat_Matrix!$AG$2:$AP$6, 8, FALSE) -> 0 | K11: =VLOOKUP(C11, Stat_Matrix!$E$2:$N$7, 6, FALSE) + (VLOOKUP(B11, Stat_Matrix!$A$2:$C$5, 3, FALSE) * VLOOKUP(C11, Stat_Matrix!$P$2:$Y$7, 6, FALSE)) + VLOOKUP(IF(ISBLANK(E11), "Balanced", E11), Stat_Matrix!$AG$2:$AP$6, 6, FALSE) -> 8 | L11: =VLOOKUP(C11, Stat_Matrix!$E$2:$N$7, 7, FALSE) + (VLOOKUP(B11, Stat_Matrix!$A$2:$C$5, 3, FALSE) * VLOOKUP(C11, Stat_Matrix!$P$2:$Y$7, 7, FALSE)) + VLOOKUP(IF(ISBLANK(E11), "Balanced", E11), Stat_Matrix!$AG$2:$AP$6, 7, FALSE) -> 19 | M11: =VLOOKUP(C11, Stat_Matrix!$E$2:$N$7, 9, FALSE) + (VLOOKUP(B11, Stat_Matrix!$A$2:$C$5, 3, FALSE) * VLOOKUP(C11, Stat_Matrix!$P$2:$Y$7, 9, FALSE)) + VLOOKUP(IF(ISBLANK(E11), "Balanced", E11), Stat_Matrix!$AG$2:$AP$6, 9, FALSE) -> 11 | N11: =VLOOKUP(C11, Stat_Matrix!$E$2:$N$7, 10, FALSE) + (VLOOKUP(B11, Stat_Matrix!$A$2:$C$5, 3, FALSE) * VLOOKUP(C11, Stat_Matrix!$P$2:$Y$7, 10, FALSE) + VLOOKUP(IF(ISBLANK(D11), "Character", D11), Stat_Matrix!$AA$2:$AE$4, 5, FALSE) + VLOOKUP(IF(ISBLANK(E11), "Balanced", E11), Stat_Matrix!$AG$2:$AP$6, 10, FALSE)) -> 0
A12: VanguardTiger | B12: =Character!C12 -> R | C12: =Character!D12 -> Fighter | D12: =Character!E12 -> Boss | E12: Offensive | F12: =ROUND(VLOOKUP(C12, Stat_Matrix!$E$2:$N$7, 2, FALSE) * VLOOKUP(B12, Stat_Matrix!$A$2:$B$5, 2, FALSE) * VLOOKUP(IF(ISBLANK(D12), "Character", D12), Stat_Matrix!$AA$2:$AD$4, 2, FALSE) * VLOOKUP(IF(ISBLANK(E12), "Balanced", E12), Stat_Matrix!$AG$2:$AP$6, 2, FALSE), 0) -> 3919 | G12: =ROUND(VLOOKUP(C12, Stat_Matrix!$E$2:$N$7, 3, FALSE) * VLOOKUP(B12, Stat_Matrix!$A$2:$B$5, 2, FALSE) * VLOOKUP(IF(ISBLANK(D12), "Character", D12), Stat_Matrix!$AA$2:$AD$4, 3, FALSE) * VLOOKUP(IF(ISBLANK(E12), "Balanced", E12), Stat_Matrix!$AG$2:$AP$6, 3, FALSE), 0) -> 2178 | H12: =ROUND(VLOOKUP(C12, Stat_Matrix!$E$2:$N$7, 4, FALSE) * VLOOKUP(B12, Stat_Matrix!$A$2:$B$5, 2, FALSE) * VLOOKUP(IF(ISBLANK(D12), "Character", D12), Stat_Matrix!$AA$2:$AD$4, 4, FALSE) * VLOOKUP(IF(ISBLANK(E12), "Balanced", E12), Stat_Matrix!$AG$2:$AP$6, 4, FALSE), 0) -> 314 | I12: =VLOOKUP(C12, Stat_Matrix!$E$2:$N$7, 5, FALSE) + (VLOOKUP(B12, Stat_Matrix!$A$2:$C$5, 3, FALSE) * VLOOKUP(C12, Stat_Matrix!$P$2:$Y$7, 5, FALSE)) + VLOOKUP(IF(ISBLANK(E12), "Balanced", E12), Stat_Matrix!$AG$2:$AP$6, 5, FALSE) -> 90 | J12: =VLOOKUP(C12, Stat_Matrix!$E$2:$N$7, 8, FALSE) + (VLOOKUP(B12, Stat_Matrix!$A$2:$C$5, 3, FALSE) * VLOOKUP(C12, Stat_Matrix!$P$2:$Y$7, 8, FALSE)) + VLOOKUP(IF(ISBLANK(E12), "Balanced", E12), Stat_Matrix!$AG$2:$AP$6, 8, FALSE) -> 10 | K12: 60 | L12: 100 | M12: 20 | N12: 25
A13: TheBoySage | B13: =Character!C13 -> UR | C13: =Character!D13 -> Assassin | D13: =Character!E13 -> Boss | E13: Balanced | F13: =ROUND(VLOOKUP(C13, Stat_Matrix!$E$2:$N$7, 2, FALSE) * VLOOKUP(B13, Stat_Matrix!$A$2:$B$5, 2, FALSE) * VLOOKUP(IF(ISBLANK(D13), "Character", D13), Stat_Matrix!$AA$2:$AD$4, 2, FALSE) * VLOOKUP(IF(ISBLANK(E13), "Balanced", E13), Stat_Matrix!$AG$2:$AP$6, 2, FALSE), 0) -> 5100 | G13: =ROUND(VLOOKUP(C13, Stat_Matrix!$E$2:$N$7, 3, FALSE) * VLOOKUP(B13, Stat_Matrix!$A$2:$B$5, 2, FALSE) * VLOOKUP(IF(ISBLANK(D13), "Character", D13), Stat_Matrix!$AA$2:$AD$4, 3, FALSE) * VLOOKUP(IF(ISBLANK(E13), "Balanced", E13), Stat_Matrix!$AG$2:$AP$6, 3, FALSE), 0) -> 4590 | H13: =ROUND(VLOOKUP(C13, Stat_Matrix!$E$2:$N$7, 4, FALSE) * VLOOKUP(B13, Stat_Matrix!$A$2:$B$5, 2, FALSE) * VLOOKUP(IF(ISBLANK(D13), "Character", D13), Stat_Matrix!$AA$2:$AD$4, 4, FALSE) * VLOOKUP(IF(ISBLANK(E13), "Balanced", E13), Stat_Matrix!$AG$2:$AP$6, 4, FALSE), 0) -> 408 | I13: =VLOOKUP(C13, Stat_Matrix!$E$2:$N$7, 5, FALSE) + (VLOOKUP(B13, Stat_Matrix!$A$2:$C$5, 3, FALSE) * VLOOKUP(C13, Stat_Matrix!$P$2:$Y$7, 5, FALSE)) + VLOOKUP(IF(ISBLANK(E13), "Balanced", E13), Stat_Matrix!$AG$2:$AP$6, 5, FALSE) -> 114 | J13: =VLOOKUP(C13, Stat_Matrix!$E$2:$N$7, 8, FALSE) + (VLOOKUP(B13, Stat_Matrix!$A$2:$C$5, 3, FALSE) * VLOOKUP(C13, Stat_Matrix!$P$2:$Y$7, 8, FALSE)) + VLOOKUP(IF(ISBLANK(E13), "Balanced", E13), Stat_Matrix!$AG$2:$AP$6, 8, FALSE) -> 19 | K13: 60 | L13: 100 | M13: 20 | N13: 25
A14: GoldHornKing | B14: =Character!C14 -> SSR | C14: =Character!D14 -> Assassin | D14: =Character!E14 -> Boss | E14: Offensive | F14: =ROUND(VLOOKUP(C14, Stat_Matrix!$E$2:$N$7, 2, FALSE) * VLOOKUP(B14, Stat_Matrix!$A$2:$B$5, 2, FALSE) * VLOOKUP(IF(ISBLANK(D14), "Character", D14), Stat_Matrix!$AA$2:$AD$4, 2, FALSE) * VLOOKUP(IF(ISBLANK(E14), "Balanced", E14), Stat_Matrix!$AG$2:$AP$6, 2, FALSE), 0) -> 4133 | G14: =ROUND(VLOOKUP(C14, Stat_Matrix!$E$2:$N$7, 3, FALSE) * VLOOKUP(B14, Stat_Matrix!$A$2:$B$5, 2, FALSE) * VLOOKUP(IF(ISBLANK(D14), "Character", D14), Stat_Matrix!$AA$2:$AD$4, 3, FALSE) * VLOOKUP(IF(ISBLANK(E14), "Balanced", E14), Stat_Matrix!$AG$2:$AP$6, 3, FALSE), 0) -> 4307 | H14: =ROUND(VLOOKUP(C14, Stat_Matrix!$E$2:$N$7, 4, FALSE) * VLOOKUP(B14, Stat_Matrix!$A$2:$B$5, 2, FALSE) * VLOOKUP(IF(ISBLANK(D14), "Character", D14), Stat_Matrix!$AA$2:$AD$4, 4, FALSE) * VLOOKUP(IF(ISBLANK(E14), "Balanced", E14), Stat_Matrix!$AG$2:$AP$6, 4, FALSE), 0) -> 331 | I14: =VLOOKUP(C14, Stat_Matrix!$E$2:$N$7, 5, FALSE) + (VLOOKUP(B14, Stat_Matrix!$A$2:$C$5, 3, FALSE) * VLOOKUP(C14, Stat_Matrix!$P$2:$Y$7, 5, FALSE)) + VLOOKUP(IF(ISBLANK(E14), "Balanced", E14), Stat_Matrix!$AG$2:$AP$6, 5, FALSE) -> 111 | J14: =VLOOKUP(C14, Stat_Matrix!$E$2:$N$7, 8, FALSE) + (VLOOKUP(B14, Stat_Matrix!$A$2:$C$5, 3, FALSE) * VLOOKUP(C14, Stat_Matrix!$P$2:$Y$7, 8, FALSE)) + VLOOKUP(IF(ISBLANK(E14), "Balanced", E14), Stat_Matrix!$AG$2:$AP$6, 8, FALSE) -> 21 | K14: 60 | L14: 100 | M14: 20 | N14: 25
A15: SilverHornKing | B15: =Character!C15 -> SSR | C15: =Character!D15 -> Assassin | D15: =Character!E15 -> Boss | E15: Offensive | F15: =ROUND(VLOOKUP(C15, Stat_Matrix!$E$2:$N$7, 2, FALSE) * VLOOKUP(B15, Stat_Matrix!$A$2:$B$5, 2, FALSE) * VLOOKUP(IF(ISBLANK(D15), "Character", D15), Stat_Matrix!$AA$2:$AD$4, 2, FALSE) * VLOOKUP(IF(ISBLANK(E15), "Balanced", E15), Stat_Matrix!$AG$2:$AP$6, 2, FALSE), 0) -> 4133 | G15: =ROUND(VLOOKUP(C15, Stat_Matrix!$E$2:$N$7, 3, FALSE) * VLOOKUP(B15, Stat_Matrix!$A$2:$B$5, 2, FALSE) * VLOOKUP(IF(ISBLANK(D15), "Character", D15), Stat_Matrix!$AA$2:$AD$4, 3, FALSE) * VLOOKUP(IF(ISBLANK(E15), "Balanced", E15), Stat_Matrix!$AG$2:$AP$6, 3, FALSE), 0) -> 4307 | H15: =ROUND(VLOOKUP(C15, Stat_Matrix!$E$2:$N$7, 4, FALSE) * VLOOKUP(B15, Stat_Matrix!$A$2:$B$5, 2, FALSE) * VLOOKUP(IF(ISBLANK(D15), "Character", D15), Stat_Matrix!$AA$2:$AD$4, 4, FALSE) * VLOOKUP(IF(ISBLANK(E15), "Balanced", E15), Stat_Matrix!$AG$2:$AP$6, 4, FALSE), 0) -> 331 | I15: =VLOOKUP(C15, Stat_Matrix!$E$2:$N$7, 5, FALSE) + (VLOOKUP(B15, Stat_Matrix!$A$2:$C$5, 3, FALSE) * VLOOKUP(C15, Stat_Matrix!$P$2:$Y$7, 5, FALSE)) + VLOOKUP(IF(ISBLANK(E15), "Balanced", E15), Stat_Matrix!$AG$2:$AP$6, 5, FALSE) -> 111 | J15: =VLOOKUP(C15, Stat_Matrix!$E$2:$N$7, 8, FALSE) + (VLOOKUP(B15, Stat_Matrix!$A$2:$C$5, 3, FALSE) * VLOOKUP(C15, Stat_Matrix!$P$2:$Y$7, 8, FALSE)) + VLOOKUP(IF(ISBLANK(E15), "Balanced", E15), Stat_Matrix!$AG$2:$AP$6, 8, FALSE) -> 21 | K15: 60 | L15: 100 | M15: 20 | N15: 25
A16: YellowWindMonster | B16: =Character!C16 -> UR | C16: =Character!D16 -> Fighter | D16: =Character!E16 -> Boss | E16: Offensive | F16: =ROUND(VLOOKUP(C16, Stat_Matrix!$E$2:$N$7, 2, FALSE) * VLOOKUP(B16, Stat_Matrix!$A$2:$B$5, 2, FALSE) * VLOOKUP(IF(ISBLANK(D16), "Character", D16), Stat_Matrix!$AA$2:$AD$4, 2, FALSE) * VLOOKUP(IF(ISBLANK(E16), "Balanced", E16), Stat_Matrix!$AG$2:$AP$6, 2, FALSE), 0) -> 6662 | G16: =ROUND(VLOOKUP(C16, Stat_Matrix!$E$2:$N$7, 3, FALSE) * VLOOKUP(B16, Stat_Matrix!$A$2:$B$5, 2, FALSE) * VLOOKUP(IF(ISBLANK(D16), "Character", D16), Stat_Matrix!$AA$2:$AD$4, 3, FALSE) * VLOOKUP(IF(ISBLANK(E16), "Balanced", E16), Stat_Matrix!$AG$2:$AP$6, 3, FALSE), 0) -> 3703 | H16: =ROUND(VLOOKUP(C16, Stat_Matrix!$E$2:$N$7, 4, FALSE) * VLOOKUP(B16, Stat_Matrix!$A$2:$B$5, 2, FALSE) * VLOOKUP(IF(ISBLANK(D16), "Character", D16), Stat_Matrix!$AA$2:$AD$4, 4, FALSE) * VLOOKUP(IF(ISBLANK(E16), "Balanced", E16), Stat_Matrix!$AG$2:$AP$6, 4, FALSE), 0) -> 533 | I16: =VLOOKUP(C16, Stat_Matrix!$E$2:$N$7, 5, FALSE) + (VLOOKUP(B16, Stat_Matrix!$A$2:$C$5, 3, FALSE) * VLOOKUP(C16, Stat_Matrix!$P$2:$Y$7, 5, FALSE)) + VLOOKUP(IF(ISBLANK(E16), "Balanced", E16), Stat_Matrix!$AG$2:$AP$6, 5, FALSE) -> 96 | J16: =VLOOKUP(C16, Stat_Matrix!$E$2:$N$7, 8, FALSE) + (VLOOKUP(B16, Stat_Matrix!$A$2:$C$5, 3, FALSE) * VLOOKUP(C16, Stat_Matrix!$P$2:$Y$7, 8, FALSE)) + VLOOKUP(IF(ISBLANK(E16), "Balanced", E16), Stat_Matrix!$AG$2:$AP$6, 8, FALSE) -> 16 | K16: 60 | L16: 100 | M16: 20 | N16: 25
